Workbook

Sheet ReadMe
B2: Human Resource Analytics - Power BI Training Dataset
B3: Prepared for classroom / self-paced Power BI training use
B5: Prepared by: | C5: Kajola Gbenga - Data Scientist & AI Engineer
B7: AsOfDate | C7: 46254 | D7: <- used by formula columns in the Employees sheet (Age, Tenure)
B9: What this workbook contains
B10: This workbook is a fully relational, star/snowflake-style Human Resource dataset built specifically for teaching Power BI end to end - from Power Query loading, through data modelling and relationships, to DAX measures and dashboard design.
B12: Tables in this workbook
B13: Employees | C13: Main employee record table (1 row per employee). Grain: one row per EmployeeID.
B14: Dim_Department | C14: Lookup table of the 10 departments. One-to-many to Employees.
B15: Dim_JobTitle | C15: Lookup table of 38 job titles across all departments and job levels. One-to-many to Employees.
B16: Dim_Location | C16: Lookup table of 15 company office / remote locations. One-to-many to Employees.
B17: Dim_Education | C17: Lookup table of education level x field combinations. One-to-many to Employees.
B18: Dim_Date | C18: A full calendar table (2018-01-01 to 2026-12-31) for time intelligence DAX. One-to-many to Employees (via HireDate/TerminationDate) and to Fact_PerformanceReviews (via ReviewDate).
B19: Fact_PerformanceReviews | C19: One row per employee per review year (multiple rows per employee). Many-to-one back to Employees.
B21: How to use this workbook
B22: Step 1 | C22: Open Power BI Desktop and use Get Data > Excel Workbook to import every sheet listed above (except this ReadMe and the Data_Dictionary sheet).
B23: Step 2 | C23: Build the data model in Model view: create relationships as described in the Data_Dictionary sheet and in the accompanying Word document / HTML files.
B24: Step 3 | C24: Write the DAX measures described in the training documents.
B25: Step 4 | C25: Build the five dashboard pages described in the training documents.
B27: Companion files | C27: This dataset ships together with: (1) a Word document containing the full curriculum - problems, column-by-column explanations and solutions; (2) an HTML task brief listing every task to complete; (3) an HTML full solution walkthrough.

Sheet Data_Dictionary
A1: Data Dictionary - every column, every table
A2: Reference this sheet while building your Power Query steps and DAX measures.
A4: Table | B4: Column | C4: Data Type | D4: Description
A5: Employees | B5: EmployeeID | C5: Text (PK) | D5: Unique employee identifier, format EMP0001. Primary key of the Employees table.
A6: Employees | B6: FirstName | C6: Text | D6: Employee's given name.
A7: Employees | B7: LastName | C7: Text | D7: Employee's family name.
A8: Employees | B8: Gender | C8: Text | D8: Self-identified gender: Female, Male, or Non-Binary. Used for diversity dashboards.
A9: Employees | B9: DateOfBirth | C9: Date | D9: Date of birth. Used to compute Age via DAX or the AgeYears formula column.
A10: Employees | B10: MaritalStatus | C10: Text | D10: Single, Married, Divorced, or Widowed.
A11: Employees | B11: DepartmentID | C11: Text (FK) | D11: Foreign key to Dim_Department.DepartmentID.
A12: Employees | B12: DepartmentName | C12: Text | D12: Denormalised department name, kept for quick filtering without a relationship.
A13: Employees | B13: JobTitleID | C13: Text (FK) | D13: Foreign key to Dim_JobTitle.JobTitleID.
A14: Employees | B14: JobTitle | C14: Text | D14: Denormalised job title text.
A15: Employees | B15: JobLevel | C15: Text | D15: Entry, Mid, Senior, Lead, Manager, Director, or Executive.
... A94: Fact_PerformanceReviews | B94: PromotionRecommended | C94: Text (Yes/No) | D94: Whether the manager recommended promotion at that review.

Sheet Employees
A1: EmployeeID | B1: FirstName | C1: LastName | D1: Gender | E1: DateOfBirth | F1: MaritalStatus | G1: DepartmentID | H1: DepartmentName | I1: JobTitleID | J1: JobTitle | K1: JobLevel | L1: LocationID | M1: EducationID | N1: ManagerID | O1: HireDate | P1: TerminationDate | Q1: EmploymentStatus | R1: TerminationReason | S1: AttritionFlag | T1: AnnualSalaryUSD | U1: StockOptionLevel | V1: OvertimeEligible | W1: WorkModel | X1: BusinessTravelFrequency | Y1: DistanceFromHomeKM | Z1: NumCompaniesWorkedPrevious | AA1: RecruitmentSource | AB1: YearsSinceLastPromotion | AC1: YearsInCurrentRole | AD1: YearsWithCurrentManager | AE1: TrainingHoursLastYear | AF1: AbsenteeismDaysLastYear | AG1: OvertimeHoursLastYear | AH1: WorkLifeBalanceScore | AI1: JobSatisfactionScore | AJ1: EnvironmentSatisfactionScore | AK1: RelationshipSatisfactionScore | AL1: PerformanceRatingLastReview | AM1: EngagementScorePercent | AN1: BenefitsEnrolled | AO1: HealthInsurancePlan | AP1: RemoteEquipmentProvided | AQ1: FullName | AR1: AgeYears | AS1: TenureYears
A2: EMP0001 | B2: Mark | C2: Johnson | D2: Male | E2: 1989-04-11 | F2: Single | G2: D09 | H2: Legal | I2: JT34 | J2: General Counsel | K2: Director | L2: L03 | M2: E42 | N2: EMP0693 | O2: 2024-03-29 | Q2: Active | S2: No | T2: 141400 | U2: 0 | V2: No | W2: Onsite | Y2: 14 | Z2: 3 | AA2: Recruitment Agency | AB2: 1.75 | AC2: 1.29 | AD2: 1.77 | AE2: 25 | AF2: 1 | AG2: 23 | AH2: 2 | AI2: 2 | AJ2: 3 | AK2: 4 | AL2: 2 | AM2: 60 | AN2: Yes | AO2: Standard | AP2: No | AQ2: =B2&" "&C2 -> Mark Johnson | AR2: =DATEDIF(E2,ReadMe!$C$7,"y") -> 37 | AS2: =ROUND(DATEDIF(O2,IF(Q2="Active",ReadMe!$C$7,P2),"m")/12,2) -> 2.33
A3: EMP0002 | B3: Denise | C3: Walker | D3: Female | E3: 1993-05-09 | F3: Widowed | G3: D09 | H3: Legal | I3: JT33 | J3: Legal Counsel | K3: Senior | L3: L13 | M3: E13 | N3: EMP0734 | O3: 2024-07-06 | Q3: Active | S3: No | T3: 79000 | U3: 0 | V3: Yes | W3: Remote | X3: Rarely | Y3: 20 | Z3: 3 | AA3: LinkedIn | AB3: 1.22 | AC3: 1.16 | AD3: 0.53 | AE3: 25 | AF3: 1 | AG3: 2 | AH3: 3 | AI3: 2 | AJ3: 3 | AK3: 2 | AL3: 1 | AM3: 81 | AN3: Yes | AO3: Premium | AP3: No | AQ3: =B3&" "&C3 -> Denise Walker | AR3: =DATEDIF(E3,ReadMe!$C$7,"y") -> 33 | AS3: =ROUND(DATEDIF(O3,IF(Q3="Active",ReadMe!$C$7,P3),"m")/12,2) -> 2.08
A4: EMP0003 | B4: Nancy | C4: Rhodes | D4: Female | E4: 1998-08-24 | F4: Married | G4: D03 | H4: Engineering | I4: JT10 | J4: Software Engineer I | K4: Entry | L4: L09 | M4: E42 | N4: EMP0349 | O4: 2020-05-07 | Q4: Active | S4: No | T4: 43600 | U4: 0 | V4: Yes | W4: Hybrid | Y4: 6 | Z4: 0 | AA4: Career Fair | AB4: 0.31 | AC4: 5.47 | AD4: 0.17 | AE4: 30 | AF4: 3 | AG4: 3 | AH4: 2 | AI4: 3 | AJ4: 1 | AK4: 2 | AL4: 3 | AM4: 46 | AN4: Yes | AO4: Standard | AP4: Yes | AQ4: =B4&" "&C4 -> Nancy Rhodes | AR4: =DATEDIF(E4,ReadMe!$C$7,"y") -> 27 | AS4: =ROUND(DATEDIF(O4,IF(Q4="Active",ReadMe!$C$7,P4),"m")/12,2) -> 6.25
A5: EMP0004 | B5: Stephanie | C5: Miller | D5: Female | E5: 1998-07-09 | F5: Widowed | G5: D04 | H5: Information Technology | I5: JT18 | J5: IT Manager | K5: Manager | L5: L12 | M5: E15 | N5: EMP0827 | O5: 2023-04-15 | Q5: Active | S5: No | T5: 99600 | U5: 0 | V5: No | W5: Onsite | X5: Rarely | Y5: 14 | Z5: 2 | AA5: Recruitment Agency | AB5: 1.87 | AC5: 2.61 | AD5: 2.18 | AE5: 30 | AF5: 7 | AG5: 0 | AH5: 2 | AI5: 3 | AJ5: 3 | AK5: 3 | AL5: 5 | AM5: 81 | AN5: Yes | AO5: Standard | AP5: Yes | AQ5: =B5&" "&C5 -> Stephanie Miller | AR5: =DATEDIF(E5,ReadMe!$C$7,"y") -> 28 | AS5: =ROUND(DATEDIF(O5,IF(Q5="Active",ReadMe!$C$7,P5),"m")/12,2) -> 3.33
A6: EMP0005 | B6: Jennifer | C6: Johnson | D6: Female | E6: 1989-07-20 | F6: Married | G6: D03 | H6: Engineering | I6: JT11 | J6: Software Engineer II | K6: Mid | L6: L13 | M6: E24 | N6: EMP0722 | O6: 2021-02-28 | Q6: Active | S6: No | T6: 78100 | U6: 3 | V6: Yes | W6: Remote | Y6: 11 | Z6: 4 | AA6: Career Fair | AB6: 2.96 | AC6: 4.57 | AD6: 0.23 | AE6: 41 | AF6: 0 | AG6: 14 | AH6: 3 | AI6: 2 | AJ6: 2 | AK6: 3 | AL6: 3 | AM6: 51 | AN6: Yes | AP6: Yes | AQ6: =B6&" "&C6 -> Jennifer Johnson | AR6: =DATEDIF(E6,ReadMe!$C$7,"y") -> 37 | AS6: =ROUND(DATEDIF(O6,IF(Q6="Active",ReadMe!$C$7,P6),"m")/12,2) -> 5.42
A7: EMP0006 | B7: Colleen | C7: Wagner | D7: Female | E7: 1988-05-02 | F7: Married | G7: D07 | H7: Operations | I7: JT29 | J7: Operations Manager | K7: Manager | L7: L08 | M7: E20 | N7: EMP0651 | O7: 2018-04-23 | Q7: Active | S7: No | T7: 99000 | U7: 0 | V7: No | W7: Hybrid | Y7: 1 | Z7: 4 | AA7: Job Portal | AB7: 4.9 | AC7: 2.74 | AD7: 1.65 | AE7: 26 | AF7: 2 | AG7: 21 | AH7: 3 | AI7: 3 | AJ7: 3 | AK7: 4 | AL7: 5 | AM7: 59 | AN7: Yes | AO7: Standard | AP7: No | AQ7: =B7&" "&C7 -> Colleen Wagner | AR7: =DATEDIF(E7,ReadMe!$C$7,"y") -> 38 | AS7: =ROUND(DATEDIF(O7,IF(Q7="Active",ReadMe!$C$7,P7),"m")/12,2) -> 8.25
A8: EMP0007 | B8: Alyssa | C8: Gonzalez | D8: Female | E8: 1982-09-06 | F8: Married | G8: D03 | H8: Engineering | I8: JT13 | J8: Lead Software Engineer | K8: Lead | L8: L11 | M8: E11 | N8: EMP0176 | O8: 2018-02-11 | Q8: Active | S8: No | T8: 125100 | U8: 0 | V8: Yes | W8: Hybrid | X8: Rarely | Y8: 21 | Z8: 4 | AA8: LinkedIn | AB8: 1.75 | AC8: 8.26 | AD8: 6.06 | AE8: 30 | AF8: 14 | AG8: 12 | AH8: 3 | AI8: 3 | AJ8: 2 | AK8: 1 | AL8: 3 | AM8: 78 | AN8: Yes | AO8: Premium | AP8: Yes | AQ8: =B8&" "&C8 -> Alyssa Gonzalez | AR8: =DATEDIF(E8,ReadMe!$C$7,"y") -> 43 | AS8: =ROUND(DATEDIF(O8,IF(Q8="Active",ReadMe!$C$7,P8),"m")/12,2) -> 8.5
A9: EMP0008 | B9: Marie | C9: Gardner | D9: Female | E9: 1985-10-07 | F9: Single | G9: D06 | H9: Finance | I9: JT26 | J9: Finance Manager | K9: Manager | L9: L12 | M9: E27 | N9: EMP0864 | O9: 2020-02-22 | Q9: Active | S9: No | T9: 108500 | U9: 0 | V9: No | W9: Hybrid | X9: Rarely | Y9: 9 | Z9: 2 | AA9: LinkedIn | AB9: 3.06 | AC9: 2.57 | AD9: 4.86 | AE9: 27 | AF9: 3 | AG9: 8 | AH9: 4 | AI9: 3 | AJ9: 3 | AK9: 2 | AL9: 3 | AM9: 65 | AN9: Yes | AO9: Standard | AP9: No | AQ9: =B9&" "&C9 -> Marie Gardner | AR9: =DATEDIF(E9,ReadMe!$C$7,"y") -> 40 | AS9: =ROUND(DATEDIF(O9,IF(Q9="Active",ReadMe!$C$7,P9),"m")/12,2) -> 6.42
A10: EMP0009 | B10: Daniel | C10: Lawrence | D10: Male | E10: 1988-02-06 | F10: Divorced | G10: D05 | H10: Human Resources | I10: JT19 | J10: HR Coordinator | K10: Entry | L10: L03 | M10: E08 | N10: EMP0581 | O10: 2023-12-07 | Q10: Active | S10: No | T10: 54100 | U10: 0 | V10: Yes | W10: Onsite | Y10: 17 | Z10: 0 | AA10: LinkedIn | AB10: 1.14 | AC10: 1.32 | AD10: 1.11 | AE10: 20 | AF10: 2 | AG10: 14 | AH10: 2 | AI10: 3 | AJ10: 3 | AK10: 3 | AL10: 3 | AM10: 72 | AN10: Yes | AO10: Standard | AP10: No | AQ10: =B10&" "&C10 -> Daniel Lawrence | AR10: =DATEDIF(E10,ReadMe!$C$7,"y") -> 38 | AS10: =ROUND(DATEDIF(O10,IF(Q10="Active",ReadMe!$C$7,P10),"m")/12,2) -> 2.67
A11: EMP0010 | B11: Robert | C11: Smith | D11: Male | E11: 1982-10-06 | F11: Divorced | G11: D09 | H11: Legal | I11: JT34 | J11: General Counsel | K11: Director | L11: L13 | M11: E31 | N11: EMP0763 | O11: 2022-02-20 | Q11: Active | S11: No | T11: 161800 | U11: 0 | V11: No | W11: Hybrid | Y11: 29 | Z11: 4 | AA11: Company Website | AB11: 1.77 | AC11: 1.62 | AD11: 2.2 | AE11: 35 | AF11: 0 | AG11: 41 | AH11: 2 | AI11: 3 | AJ11: 4 | AK11: 3 | AL11: 4 | AM11: 49 | AN11: Yes | AO11: Basic | AP11: No | AQ11: =B11&" "&C11 -> Robert Smith | AR11: =DATEDIF(E11,ReadMe!$C$7,"y") -> 43 | AS11: =ROUND(DATEDIF(O11,IF(Q11="Active",ReadMe!$C$7,P11),"m")/12,2) -> 4.5
A12: EMP0011 | B12: Robert | C12: Wolfe | D12: Male | E12: 2005-02-02 | F12: Single | G12: D03 | H12: Engineering | I12: JT10 | J12: Software Engineer I | K12: Entry | L12: L01 | M12: E01 | N12: EMP0094 | O12: 2026-01-31 | Q12: Active | S12: No | T12: 56000 | U12: 1 | V12: Yes | W12: Remote | Y12: 16 | Z12: 3 | AA12: LinkedIn | AB12: 0.24 | AC12: 0.2 | AD12: 0.36 | AE12: 27 | AF12: 2 | AG12: 9 | AH12: 3 | AI12: 4 | AJ12: 3 | AK12: 1 | AL12: 4 | AM12: 90 | AN12: Yes | AO12: Standard | AP12: No | AQ12: =B12&" "&C12 -> Robert Wolfe | AR12: =DATEDIF(E12,ReadMe!$C$7,"y") -> 21 | AS12: =ROUND(DATEDIF(O12,IF(Q12="Active",ReadMe!$C$7,P12),"m")/12,2) -> 0.5
A13: EMP0012 | B13: Gerald | C13: Moore | D13: Male | E13: 1983-01-27 | F13: Single | G13: D05 | H13: Human Resources | I13: JT22 | J13: HR Manager | K13: Manager | L13: L09 | M13: E08 | N13: EMP0480 | O13: 2020-09-23 | Q13: Active | S13: No | T13: 134600 | U13: 2 | V13: No | W13: Remote | Y13: 24 | Z13: 3 | AA13: Company Website | AB13: 1.34 | AC13: 0.86 | AD13: 0.88 | AE13: 42 | AF13: 3 | AG13: 19 | AH13: 3 | AI13: 3 | AJ13: 3 | AK13: 3 | AL13: 4 | AM13: 68 | AN13: Yes | AO13: Basic | AP13: Yes | AQ13: =B13&" "&C13 -> Gerald Moore | AR13: =DATEDIF(E13,ReadMe!$C$7,"y") -> 43 | AS13: =ROUND(DATEDIF(O13,IF(Q13="Active",ReadMe!$C$7,P13),"m")/12,2) -> 5.83
A14: EMP0013 | B14: Tyler | C14: Rogers | D14: Male | E14: 2004-11-24 | F14: Divorced | G14: D07 | H14: Operations | I14: JT28 | J14: Operations Analyst | K14: Entry | L14: L14 | M14: E10 | N14: EMP0977 | O14: 2025-05-30 | P14: 2025-12-17 | Q14: Terminated | R14: Voluntary - Better Opportunity | S14: Yes | T14: 51600 | U14: 2 | V14: Yes | W14: Hybrid | Y14: 2 | Z14: 2 | AA14: Recruitment Agency | AB14: 0.08 | AC14: 0.13 | AD14: 0.39 | AE14: 36 | AF14: 5 | AG14: 14 | AH14: 2 | AI14: 2 | AJ14: 4 | AK14: 2 | AL14: 4 | AM14: 46 | AN14: Yes | AO14: Basic | AP14: No | AQ14: =B14&" "&C14 -> Tyler Rogers | AR14: =DATEDIF(E14,ReadMe!$C$7,"y") -> 21 | AS14: =ROUND(DATEDIF(O14,IF(Q14="Active",ReadMe!$C$7,P14),"m")/12,2) -> 0.5
A15: EMP0014 | B15: Brandon | C15: Davis | D15: Male | E15: 1996-07-04 | F15: Married | G15: D08 | H15: Customer Support | I15: JT31 | J15: Senior Support Representative | K15: Senior | L15: L03 | M15: E27 | N15: EMP0520 | O15: 2018-05-25 | Q15: Active | S15: No | T15: 95300 | U15: 0 | V15: Yes | W15: Hybrid | X15: Rarely | Y15: 13 | Z15: 1 | AA15: Job Portal | AB15: 0.57 | AC15: 0.24 | AD15: 2.04 | AE15: 34 | AF15: 22 | AG15: 66 | AH15: 4 | AI15: 2 | AJ15: 3 | AK15: 4 | AL15: 2 | AM15: 79 | AN15: Yes | AO15: Premium | AP15: No | AQ15: =B15&" "&C15 -> Brandon Davis | AR15: =DATEDIF(E15,ReadMe!$C$7,"y") -> 30 | AS15: =ROUND(DATEDIF(O15,IF(Q15="Active",ReadMe!$C$7,P15),"m")/12,2) -> 8.17
A16: EMP0015 | B16: Ryan | C16: Munoz | D16: Male | E16: 2003-11-28 | F16: Divorced | G16: D07 | H16: Operations | I16: JT29 | J16: Operations Manager | K16: Manager | L16: L08 | M16: E13 | N16: EMP0115 | O16: 2024-05-06 | Q16: Active | S16: No | T16: 122000 | U16: 0 | V16: No | W16: Hybrid | Y16: 51 | Z16: 0 | AA16: LinkedIn | AB16: 1.84 | AC16: 0.01 | AD16: 1.84 | AE16: 26 | AF16: 2 | AG16: 0 | AH16: 3 | AI16: 3 | AJ16: 3 | AK16: 3 | AL16: 3 | AM16: 70 | AN16: Yes | AO16: Premium | AP16: No | AQ16: =B16&" "&C16 -> Ryan Munoz | AR16: =DATEDIF(E16,ReadMe!$C$7,"y") -> 22 | AS16: =ROUND(DATEDIF(O16,IF(Q16="Active",ReadMe!$C$7,P16),"m")/12,2) -> 2.25
A17: EMP0016 | B17: Renee | C17: Blair | D17: Female | E17: 1987-07-21 | F17: Married | G17: D06 | H17: Finance | I17: JT27 | J17: Director of Finance | K17: Director | L17: L03 | M17: E33 | N17: EMP0779 | O17: 2025-03-09 | Q17: Active | S17: No | T17: 188300 | U17: 1 | V17: No | W17: Onsite | X17: Rarely | Y17: 37 | Z17: 2 | AA17: LinkedIn | AB17: 0.57 | AC17: 0.33 | AD17: 0.17 | AE17: 32 | AF17: 2 | AG17: 31 | AH17: 4 | AI17: 3 | AJ17: 1 | AK17: 2 | AL17: 3 | AM17: 49 | AN17: Yes | AO17: Basic | AP17: Yes | AQ17: =B17&" "&C17 -> Renee Blair | AR17: =DATEDIF(E17,ReadMe!$C$7,"y") -> 39 | AS17: =ROUND(DATEDIF(O17,IF(Q17="Active",ReadMe!$C$7,P17),"m")/12,2) -> 1.42
A18: EMP0017 | B18: Joshua | C18: Dudley | D18: Male | E18: 1997-06-04 | F18: Married | G18: D01 | H18: Sales | I18: JT03 | J18: Senior Account Executive | K18: Senior | L18: L12 | M18: E50 | N18: EMP0952 | O18: 2023-08-28 | Q18: Active | S18: No | T18: 110200 | U18: 2 | V18: Yes | W18: Hybrid | Y18: 5 | Z18: 2 | AA18: Company Website | AB18: 1.54 | AC18: 1.1 | AD18: 2.07 | AE18: 24 | AF18: 1 | AG18: 18 | AH18: 3 | AI18: 2 | AJ18: 3 | AK18: 4 | AL18: 2 | AM18: 95 | AN18: Yes | AO18: Basic | AP18: Yes | AQ18: =B18&" "&C18 -> Joshua Dudley | AR18: =DATEDIF(E18,ReadMe!$C$7,"y") -> 29 | AS18: =ROUND(DATEDIF(O18,IF(Q18="Active",ReadMe!$C$7,P18),"m")/12,2) -> 2.92
A19: EMP0018 | B19: Jamie | C19: Arnold | D19: Female | E19: 1993-09-30 | F19: Divorced | G19: D05 | H19: Human Resources | I19: JT21 | J19: Senior HR Business Partner | K19: Senior | L19: L11 | M19: E31 | N19: EMP0254 | O19: 2022-07-22 | Q19: Active | S19: No | T19: 111800 | U19: 2 | V19: Yes | W19: Onsite | X19: Frequently | Y19: 8 | Z19: 2 | AA19: Employee Referral | AB19: 1.38 | AC19: 0.51 | AD19: 1.27 | AE19: 30 | AF19: 10 | AG19: 12 | AH19: 2 | AI19: 4 | AJ19: 3 | AK19: 3 | AL19: 3 | AM19: 57 | AN19: Yes | AO19: Basic | AP19: Yes | AQ19: =B19&" "&C19 -> Jamie Arnold | AR19: =DATEDIF(E19,ReadMe!$C$7,"y") -> 32 | AS19: =ROUND(DATEDIF(O19,IF(Q19="Active",ReadMe!$C$7,P19),"m")/12,2) -> 4
A20: EMP0019 | B20: Ronald | C20: Montgomery | D20: Male | E20: 1979-05-12 | F20: Divorced | G20: D06 | H20: Finance | I20: JT27 | J20: Director of Finance | K20: Director | L20: L15 | M20: E43 | N20: EMP0928 | O20: 2026-06-30 | Q20: Active | S20: No | T20: 152700 | U20: 3 | V20: No | W20: Remote | Y20: 18 | Z20: 2 | AA20: Employee Referral | AB20: 0.06 | AC20: 0.06 | AD20: 0.06 | AE20: 17 | AF20: 6 | AG20: 1 | AH20: 3 | AI20: 4 | AJ20: 2 | AK20: 4 | AL20: 3 | AM20: 78 | AN20: Yes | AO20: Basic | AP20: Yes | AQ20: =B20&" "&C20 -> Ronald Montgomery | AR20: =DATEDIF(E20,ReadMe!$C$7,"y") -> 47 | AS20: =ROUND(DATEDIF(O20,IF(Q20="Active",ReadMe!$C$7,P20),"m")/12,2) -> 0.08
A21: EMP0020 | B21: Scott | C21: Ray | D21: Male | E21: 1980-12-26 | F21: Widowed | G21: D06 | H21: Finance | I21: JT27 | J21: Director of Finance | K21: Director | L21: L05 | M21: E24 | N21: EMP0904 | O21: 2024-07-10 | Q21: Active | S21: No | T21: 155300 | U21: 3 | V21: No | W21: Hybrid | Y21: 1 | Z21: 0 | AA21: LinkedIn | AB21: 1.47 | AC21: 1.66 | AD21: 0.43 | AE21: 9 | AF21: 11 | AG21: 0 | AH21: 3 | AI21: 3 | AJ21: 3 | AK21: 4 | AL21: 4 | AM21: 78 | AN21: Yes | AO21: Premium | AP21: No | AQ21: =B21&" "&C21 -> Scott Ray | AR21: =DATEDIF(E21,ReadMe!$C$7,"y") -> 45 | AS21: =ROUND(DATEDIF(O21,IF(Q21="Active",ReadMe!$C$7,P21),"m")/12,2) -> 2.08
A22: EMP0021 | B22: Michael | C22: Williams | D22: Male | E22: 1988-05-24 | F22: Single | G22: D05 | H22: Human Resources | I22: JT21 | J22: Senior HR Business Partner | K22: Senior | L22: L08 | M22: E11 | N22: EMP0421 | O22: 2025-03-08 | Q22: Active | S22: No | T22: 105500 | U22: 1 | V22: Yes | W22: Hybrid | X22: Frequently | Y22: 13 | Z22: 2 | AA22: Company Website | AB22: 0.85 | AC22: 0.71 | AD22: 0.7 | AE22: 37 | AF22: 1 | AG22: 3 | AH22: 3 | AI22: 3 | AJ22: 2 | AK22: 3 | AL22: 4 | AM22: 59 | AN22: No | AO22: Basic | AP22: Yes | AQ22: =B22&" "&C22 -> Michael Williams | AR22: =DATEDIF(E22,ReadMe!$C$7,"y") -> 38 | AS22: =ROUND(DATEDIF(O22,IF(Q22="Active",ReadMe!$C$7,P22),"m")/12,2) -> 1.42
A23: EMP0022 | B23: Darren | C23: Roberts | D23: Male | E23: 1991-07-29 | F23: Married | G23: D03 | H23: Engineering | I23: JT15 | J23: Director of Engineering | K23: Director | L23: L01 | M23: E37 | N23: EMP0112 | O23: 2022-07-18 | Q23: Active | S23: No | T23: 175500 | U23: 0 | V23: No | W23: Remote | Y23: 22 | Z23: 3 | AA23: Recruitment Agency | AB23: 1.59 | AC23: 0.52 | AD23: 2.47 | AE23: 28 | AF23: 2 | AG23: 14 | AH23: 3 | AI23: 4 | AJ23: 3 | AK23: 2 | AL23: 1 | AM23: 63 | AN23: Yes | AO23: Basic | AP23: Yes | AQ23: =B23&" "&C23 -> Darren Roberts | AR23: =DATEDIF(E23,ReadMe!$C$7,"y") -> 35 | AS23: =ROUND(DATEDIF(O23,IF(Q23="Active",ReadMe!$C$7,P23),"m")/12,2) -> 4.08
A24: EMP0023 | B24: Angela | C24: Hall | D24: Female | E24: 2005-04-05 | F24: Single | G24: D02 | H24: Marketing | I24: JT06 | J24: Marketing Coordinator | K24: Entry | L24: L06 | M24: E17 | N24: EMP0883 | O24: 2026-01-27 | Q24: Active | S24: No | T24: 46400 | U24: 0 | V24: Yes | W24: Onsite | Y24: 7 | Z24: 2 | AA24: Employee Referral | AB24: 0.46 | AC24: 0.26 | AD24: 0.2 | AE24: 23 | AF24: 7 | AG24: 30 | AH24: 3 | AI24: 4 | AJ24: 3 | AK24: 3 | AL24: 2 | AM24: 88 | AN24: Yes | AO24: Premium | AP24: No | AQ24: =B24&" "&C24 -> Angela Hall | AR24: =DATEDIF(E24,ReadMe!$C$7,"y") -> 21 | AS24: =ROUND(DATEDIF(O24,IF(Q24="Active",ReadMe!$C$7,P24),"m")/12,2) -> 0.5
A25: EMP0024 | B25: Brian | C25: Ramirez | D25: Male | E25: 1998-08-20 | F25: Widowed | G25: D08 | H25: Customer Support | I25: JT30 | J25: Customer Support Representative | K25: Entry | L25: L02 | M25: E31 | N25: EMP0925 | O25: 2018-07-24 | P25: 2024-04-02 | Q25: Terminated | R25: Voluntary - Further Education | S25: Yes | T25: 48800 | U25: 0 | V25: Yes | W25: Onsite | X25: Rarely | Y25: 54 | Z25: 1 | AA25: Employee Referral | AB25: 4.92 | AC25: 4.17 | AD25: 6.58 | AE25: 49 | AF25: 8 | AG25: 37 | AH25: 3 | AI25: 2 | AJ25: 3 | AK25: 2 | AL25: 3 | AM25: 73 | AN25: Yes | AO25: Standard | AP25: Yes | AQ25: =B25&" "&C25 -> Brian Ramirez | AR25: =DATEDIF(E25,ReadMe!$C$7,"y") -> 28 | AS25: =ROUND(DATEDIF(O25,IF(Q25="Active",ReadMe!$C$7,P25),"m")/12,2) -> 5.67
A26: EMP0025 | B26: Cynthia | C26: Diaz | D26: Non-Binary | E26: 1990-01-09 | F26: Divorced | G26: D06 | H26: Finance | I26: JT24 | J26: Financial Analyst | K26: Entry | L26: L05 | M26: E31 | N26: EMP0499 | O26: 2023-04-16 | Q26: Active | S26: No | T26: 43300 | U26: 1 | V26: Yes | W26: Onsite | Y26: 12 | Z26: 2 | AA26: LinkedIn | AB26: 0.14 | AC26: 0.69 | AD26: 0.16 | AE26: 35 | AF26: 1 | AG26: 31 | AH26: 3 | AI26: 1 | AJ26: 1 | AK26: 2 | AL26: 3 | AM26: 62 | AN26: Yes | AO26: Premium | AP26: Yes | AQ26: =B26&" "&C26 -> Cynthia Diaz | AR26: =DATEDIF(E26,ReadMe!$C$7,"y") -> 36 | AS26: =ROUND(DATEDIF(O26,IF(Q26="Active",ReadMe!$C$7,P26),"m")/12,2) -> 3.33
A27: EMP0026 | B27: Mitchell | C27: Clark | D27: Non-Binary | E27: 1987-11-26 | F27: Single | G27: D07 | H27: Operations | I27: JT29 | J27: Operations Manager | K27: Manager | L27: L04 | M27: E46 | N27: EMP0162 | O27: 2025-08-25 | P27: 2026-02-05 | Q27: Terminated | R27: Voluntary - Personal Reasons | S27: Yes | T27: 124000 | U27: 0 | V27: No | W27: Remote | Y27: 1 | Z27: 1 | AA27: Career Fair | AB27: 0.49 | AC27: 0.3 | AD27: 0.19 | AE27: 28 | AF27: 0 | AG27: 0 | AH27: 3 | AI27: 3 | AJ27: 2 | AK27: 3 | AL27: 4 | AM27: 60 | AN27: No | AO27: Basic | AP27: Yes | AQ27: =B27&" "&C27 -> Mitchell Clark | AR27: =DATEDIF(E27,ReadMe!$C$7,"y") -> 38 | AS27: =ROUND(DATEDIF(O27,IF(Q27="Active",ReadMe!$C$7,P27),"m")/12,2) -> 0.42
A28: EMP0027 | B28: Debra | C28: Zuniga | D28: Female | E28: 1993-09-17 | F28: Single | G28: D06 | H28: Finance | I28: JT26 | J28: Finance Manager | K28: Manager | L28: L02 | M28: E34 | N28: EMP0912 | O28: 2018-04-26 | Q28: Active | S28: No | T28: 124800 | U28: 1 | V28: No | W28: Onsite | X28: Frequently | Y28: 1 | Z28: 4 | AA28: Recruitment Agency | AB28: 5.03 | AC28: 2.35 | AD28: 1.89 | AE28: 32 | AF28: 2 | AG28: 16 | AH28: 3 | AI28: 2 | AJ28: 2 | AK28: 3 | AL28: 3 | AM28: 100 | AN28: Yes | AO28: Standard | AP28: No | AQ28: =B28&" "&C28 -> Debra Zuniga | AR28: =DATEDIF(E28,ReadMe!$C$7,"y") -> 32 | AS28: =ROUND(DATEDIF(O28,IF(Q28="Active",ReadMe!$C$7,P28),"m")/12,2) -> 8.25
A29: EMP0028 | B29: Maria | C29: Lynch | D29: Female | E29: 1976-11-16 | F29: Married | G29: D10 | H29: Executive | I29: JT36 | J29: Chief Financial Officer | K29: Executive | L29: L10 | M29: E20 | O29: 2021-07-25 | Q29: Active | S29: No | T29: 298900 | U29: 1 | V29: No | W29: Onsite | X29: Rarely | Y29: 25 | Z29: 2 | AA29: Job Portal | AB29: 3.96 | AC29: 3.47 | AD29: 1.31 | AE29: 13 | AF29: 0 | AG29: 44 | AH29: 2 | AI29: 4 | AJ29: 1 | AK29: 3 | AL29: 1 | AM29: 77 | AN29: Yes | AO29: Basic | AP29: No | AQ29: =B29&" "&C29 -> Maria Lynch | AR29: =DATEDIF(E29,ReadMe!$C$7,"y") -> 49 | AS29: =ROUND(DATEDIF(O29,IF(Q29="Active",ReadMe!$C$7,P29),"m")/12,2) -> 5
A30: EMP0029 | B30: Carolyn | C30: Daniel | D30: Female | E30: 2003-03-26 | F30: Divorced | G30: D03 | H30: Engineering | I30: JT10 | J30: Software Engineer I | K30: Entry | L30: L10 | M30: E31 | N30: EMP0076 | O30: 2025-03-01 | P30: 2026-04-13 | Q30: Terminated | R30: Involuntary - Performance | S30: Yes | T30: 51400 | U30: 1 | V30: Yes | W30: Onsite | X30: Rarely | Y30: 14 | Z30: 2 | AA30: LinkedIn | AB30: 1.37 | AC30: 0.05 | AD30: 1.08 | AE30: 36 | AF30: 0 | AG30: 20 | AH30: 3 | AI30: 3 | AJ30: 3 | AK30: 3 | AL30: 3 | AM30: 60 | AN30: Yes | AP30: Yes | AQ30: =B30&" "&C30 -> Carolyn Daniel | AR30: =DATEDIF(E30,ReadMe!$C$7,"y") -> 23 | AS30: =ROUND(DATEDIF(O30,IF(Q30="Active",ReadMe!$C$7,P30),"m")/12,2) -> 1.08
A31: EMP0030 | B31: Christopher | C31: Gray | D31: Male | E31: 1989-04-26 | F31: Single | G31: D09 | H31: Legal | I31: JT34 | J31: General Counsel | K31: Director | L31: L02 | M31: E02 | N31: EMP0557 | O31: 2023-02-02 | Q31: Active | S31: No | T31: 188400 | U31: 2 | V31: No | W31: Onsite | X31: Frequently | Y31: 7 | Z31: 5 | AA31: Company Website | AB31: 1.92 | AC31: 2.96 | AD31: 1.65 | AE31: 17 | AF31: 1 | AG31: 53 | AH31: 1 | AI31: 4 | AJ31: 3 | AK31: 3 | AL31: 2 | AM31: 87 | AN31: No | AO31: Premium | AP31: No | AQ31: =B31&" "&C31 -> Christopher Gray | AR31: =DATEDIF(E31,ReadMe!$C$7,"y") -> 37 | AS31: =ROUND(DATEDIF(O31,IF(Q31="Active",ReadMe!$C$7,P31),"m")/12,2) -> 3.5
A32: EMP0031 | B32: William | C32: Bowman | D32: Male | E32: 1997-09-22 | F32: Married | G32: D03 | H32: Engineering | I32: JT14 | J32: Engineering Manager | K32: Manager | L32: L09 | M32: E06 | N32: EMP0912 | O32: 2025-08-15 | Q32: Active | S32: No | T32: 110000 | U32: 0 | V32: No | W32: Onsite | X32: Rarely | Y32: 17 | Z32: 3 | AA32: Job Portal | AB32: 0.77 | AC32: 0.83 | AD32: 0.51 | AE32: 51 | AF32: 7 | AG32: 2 | AH32: 1 | AI32: 3 | AJ32: 4 | AK32: 2 | AL32: 3 | AM32: 56 | AN32: Yes | AO32: Standard | AP32: Yes | AQ32: =B32&" "&C32 -> William Bowman | AR32: =DATEDIF(E32,ReadMe!$C$7,"y") -> 28 | AS32: =ROUND(DATEDIF(O32,IF(Q32="Active",ReadMe!$C$7,P32),"m")/12,2) -> 1
A33: EMP0032 | B33: Kristin | C33: Cohen | D33: Female | E33: 1990-03-07 | F33: Single | G33: D05 | H33: Human Resources | I33: JT23 | J33: Director of Human Resources | K33: Director | L33: L08 | M33: E18 | N33: EMP0258 | O33: 2024-06-09 | Q33: Active | S33: No | T33: 151600 | U33: 1 | V33: No | W33: Hybrid | X33: Rarely | Y33: 8 | Z33: 1 | AA33: Employee Referral | AB33: 0.75 | AC33: 1.75 | AD33: 0.03 | AE33: 21 | AF33: 2 | AG33: 14 | AH33: 3 | AI33: 2 | AJ33: 2 | AK33: 3 | AL33: 2 | AM33: 66 | AN33: Yes | AO33: Basic | AP33: No | AQ33: =B33&" "&C33 -> Kristin Cohen | AR33: =DATEDIF(E33,ReadMe!$C$7,"y") -> 36 | AS33: =ROUND(DATEDIF(O33,IF(Q33="Active",ReadMe!$C$7,P33),"m")/12,2) -> 2.17
A34: EMP0033 | B34: Ryan | C34: Parsons | D34: Male | E34: 1991-08-07 | F34: Widowed | G34: D03 | H34: Engineering | I34: JT15 | J34: Director of Engineering | K34: Director | L34: L09 | M34: E31 | N34: EMP0269 | O34: 2026-06-05 | Q34: Active | S34: No | T34: 185600 | U34: 1 | V34: No | W34: Hybrid | X34: Rarely | Y34: 31 | Z34: 0 | AA34: Recruitment Agency | AB34: 0.01 | AC34: 0.03 | AD34: 0.03 | AE34: 57 | AF34: 0 | AG34: 16 | AH34: 3 | AI34: 2 | AJ34: 4 | AK34: 3 | AL34: 2 | AM34: 74 | AN34: Yes | AO34: Basic | AP34: Yes | AQ34: =B34&" "&C34 -> Ryan Parsons | AR34: =DATEDIF(E34,ReadMe!$C$7,"y") -> 35 | AS34: =ROUND(DATEDIF(O34,IF(Q34="Active",ReadMe!$C$7,P34),"m")/12,2) -> 0.17
A35: EMP0034 | B35: Daryl | C35: Johnson | D35: Male | E35: 1985-07-04 | F35: Married | G35: D01 | H35: Sales | I35: JT05 | J35: Director of Sales | K35: Director | L35: L05 | M35: E35 | N35: EMP0855 | O35: 2025-09-30 | Q35: Active | S35: No | T35: 170800 | U35: 2 | V35: No | W35: Onsite | Y35: 6 | Z35: 1 | AA35: Campus Hiring | AB35: 0.35 | AC35: 0.51 | AD35: 0.68 | AE35: 38 | AF35: 2 | AG35: 17 | AH35: 3 | AI35: 4 | AJ35: 2 | AK35: 2 | AL35: 4 | AM35: 87 | AN35: Yes | AO35: Premium | AP35: Yes | AQ35: =B35&" "&C35 -> Daryl Johnson | AR35: =DATEDIF(E35,ReadMe!$C$7,"y") -> 41 | AS35: =ROUND(DATEDIF(O35,IF(Q35="Active",ReadMe!$C$7,P35),"m")/12,2) -> 0.83
A36: EMP0035 | B36: Emily | C36: Adams | D36: Female | E36: 1988-08-09 | F36: Divorced | G36: D10 | H36: Executive | I36: JT36 | J36: Chief Financial Officer | K36: Executive | L36: L13 | M36: E29 | O36: 2018-04-05 | Q36: Active | S36: No | T36: 257000 | U36: 0 | V36: No | W36: Onsite | Y36: 16 | Z36: 3 | AA36: Career Fair | AB36: 7.14 | AC36: 5.56 | AD36: 3.37 | AE36: 20 | AF36: 1 | AG36: 7 | AH36: 2 | AI36: 4 | AJ36: 2 | AK36: 3 | AL36: 2 | AM36: 87 | AN36: Yes | AO36: Basic | AP36: No | AQ36: =B36&" "&C36 -> Emily Adams | AR36: =DATEDIF(E36,ReadMe!$C$7,"y") -> 38 | AS36: =ROUND(DATEDIF(O36,IF(Q36="Active",ReadMe!$C$7,P36),"m")/12,2) -> 8.33
A37: EMP0036 | B37: Daniel | C37: Hahn | D37: Male | E37: 1991-10-16 | F37: Married | G37: D03 | H37: Engineering | I37: JT14 | J37: Engineering Manager | K37: Manager | L37: L04 | M37: E26 | N37: EMP1000 | O37: 2019-07-24 | Q37: Active | S37: No | T37: 138700 | U37: 0 | V37: No | W37: Onsite | Y37: 26 | Z37: 4 | AA37: Campus Hiring | AB37: 3.96 | AC37: 4.33 | AD37: 1.07 | AE37: 37 | AF37: 0 | AG37: 39 | AH37: 4 | AI37: 4 | AJ37: 3 | AK37: 2 | AL37: 3 | AM37: 73 | AN37: Yes | AO37: Premium | AP37: No | AQ37: =B37&" "&C37 -> Daniel Hahn | AR37: =DATEDIF(E37,ReadMe!$C$7,"y") -> 34 | AS37: =ROUND(DATEDIF(O37,IF(Q37="Active",ReadMe!$C$7,P37),"m")/12,2) -> 7
A38: EMP0037 | B38: Sherri | C38: Edwards | D38: Female | E38: 1996-03-10 | F38: Married | G38: D08 | H38: Customer Support | I38: JT31 | J38: Senior Support Representative | K38: Senior | L38: L02 | M38: E28 | N38: EMP0885 | O38: 2019-01-10 | Q38: Active | S38: No | T38: 103000 | U38: 1 | V38: Yes | W38: Remote | Y38: 5 | Z38: 2 | AA38: Job Portal | AB38: 4.42 | AC38: 4.52 | AD38: 3.35 | AE38: 39 | AF38: 0 | AG38: 15 | AH38: 4 | AI38: 1 | AJ38: 2 | AK38: 3 | AL38: 3 | AM38: 47 | AN38: Yes | AO38: Standard | AP38: No | AQ38: =B38&" "&C38 -> Sherri Edwards | AR38: =DATEDIF(E38,ReadMe!$C$7,"y") -> 30 | AS38: =ROUND(DATEDIF(O38,IF(Q38="Active",ReadMe!$C$7,P38),"m")/12,2) -> 7.58
A39: EMP0038 | B39: Mary | C39: Foster | D39: Female | E39: 2002-02-12 | F39: Married | G39: D07 | H39: Operations | I39: JT28 | J39: Operations Analyst | K39: Entry | L39: L15 | M39: E06 | N39: EMP0229 | O39: 2022-06-29 | P39: 2025-04-26 | Q39: Terminated | R39: Voluntary - Relocation | S39: Yes | T39: 52000 | U39: 0 | V39: Yes | W39: Onsite | X39: Rarely | Y39: 1 | Z39: 3 | AA39: Campus Hiring | AB39: 0.03 | AC39: 0.56 | AD39: 0.74 | AE39: 10 | AF39: 11 | AG39: 1 | AH39: 2 | AI39: 1 | AJ39: 2 | AK39: 4 | AL39: 4 | AM39: 78 | AN39: Yes | AO39: Basic | AP39: Yes | AQ39: =B39&" "&C39 -> Mary Foster | AR39: =DATEDIF(E39,ReadMe!$C$7,"y") -> 24 | AS39: =ROUND(DATEDIF(O39,IF(Q39="Active",ReadMe!$C$7,P39),"m")/12,2) -> 2.75
A40: EMP0039 | B40: Suzanne | C40: Ellis | D40: Female | E40: 1987-04-10 | F40: Divorced | G40: D10 | H40: Executive | I40: JT35 | J40: Chief Executive Officer | K40: Executive | L40: L11 | M40: E10 | O40: 2022-10-07 | Q40: Active | S40: No | T40: 323700 | U40: 0 | V40: No | W40: Hybrid | Y40: 1 | Z40: 1 | AA40: Employee Referral | AB40: 2.84 | AC40: 2.58 | AD40: 2.05 | AE40: 14 | AF40: 0 | AG40: 37 | AH40: 3 | AI40: 2 | AJ40: 3 | AK40: 3 | AL40: 2 | AM40: 73 | AN40: Yes | AO40: Basic | AP40: No | AQ40: =B40&" "&C40 -> Suzanne Ellis | AR40: =DATEDIF(E40,ReadMe!$C$7,"y") -> 39 | AS40: =ROUND(DATEDIF(O40,IF(Q40="Active",ReadMe!$C$7,P40),"m")/12,2) -> 3.83
...

Sheet Dim_Department
A1: DepartmentID | B1: DepartmentName | C1: Division | D1: BusinessUnit | E1: DepartmentHeadName | F1: DepartmentBudgetUSD
A2: D01 | B2: Sales | C2: Commercial | D2: Revenue Generation | E2: Adaeze Okafor | F2: 4200000
A3: D02 | B3: Marketing | C3: Commercial | D3: Revenue Generation | E3: Michael Chen | F3: 2100000
A4: D03 | B4: Engineering | C4: Technology | D4: Product & Technology | E4: Sarah Whitfield | F4: 6800000
A5: D04 | B5: Information Technology | C5: Technology | D5: Product & Technology | E5: David Okonkwo | F5: 3100000
A6: D05 | B6: Human Resources | C6: Corporate | D6: People & Culture | E6: Funmilayo Adeyemi | F6: 1200000
A7: D06 | B7: Finance | C7: Corporate | D7: Finance & Legal | E7: James Whitmore | F7: 1600000
A8: D07 | B8: Operations | C8: Operations | D8: Operations & Supply | E8: Grace Muthoni | F8: 2600000
A9: D08 | B9: Customer Support | C9: Operations | D9: Operations & Supply | E9: Daniel Ibrahim | F9: 1400000
A10: D09 | B10: Legal | C10: Corporate | D10: Finance & Legal | E10: Patricia Nwosu | F10: 900000
A11: D10 | B11: Executive | C11: Corporate | D11: Leadership | E11: Chukwuemeka Eze | F11: 1100000

Sheet Dim_JobTitle
A1: JobTitleID | B1: JobTitle | C1: JobLevel | D1: JobFamily | E1: DepartmentID
A2: JT01 | B2: Sales Development Representative | C2: Entry | D2: Sales | E2: D01
A3: JT02 | B3: Account Executive | C3: Mid | D3: Sales | E3: D01
A4: JT03 | B4: Senior Account Executive | C4: Senior | D4: Sales | E4: D01
A5: JT04 | B5: Sales Manager | C5: Manager | D5: Sales | E5: D01
A6: JT05 | B6: Director of Sales | C6: Director | D6: Sales | E6: D01
A7: JT06 | B7: Marketing Coordinator | C7: Entry | D7: Marketing | E7: D02
A8: JT07 | B8: Marketing Specialist | C8: Mid | D8: Marketing | E8: D02
A9: JT08 | B9: Senior Marketing Specialist | C9: Senior | D9: Marketing | E9: D02
A10: JT09 | B10: Marketing Manager | C10: Manager | D10: Marketing | E10: D02
A11: JT10 | B11: Software Engineer I | C11: Entry | D11: Engineering | E11: D03
A12: JT11 | B12: Software Engineer II | C12: Mid | D12: Engineering | E12: D03
... A39: JT38 | B39: Chief People Officer | C39: Executive | D39: Executive | E39: D10

Sheet Dim_Location
A1: LocationID | B1: City | C1: StateProvince | D1: Country | E1: Region | F1: OfficeType
A2: L01 | B2: Lagos | C2: Lagos State | D2: Nigeria | E2: Africa | F2: HQ
A3: L02 | B3: Abuja | C3: FCT | D3: Nigeria | E3: Africa | F3: Regional Office
A4: L03 | B4: Nairobi | C4: Nairobi County | D4: Kenya | E4: Africa | F4: Regional Office
A5: L04 | B5: Accra | C5: Greater Accra | D5: Ghana | E5: Africa | F5: Regional Office
A6: L05 | B6: Johannesburg | C6: Gauteng | D6: South Africa | E6: Africa | F6: Regional Office
A7: L06 | B7: London | C7: England | D7: United Kingdom | E7: EMEA | F7: Regional Office
A8: L07 | B8: Dublin | C8: Leinster | D8: Ireland | E8: EMEA | F8: Regional Office
A9: L08 | B9: New York | C9: New York | D9: United States | E9: North America | F9: Regional Office
A10: L09 | B10: Austin | C10: Texas | D10: United States | E10: North America | F10: Regional Office
A11: L10 | B11: Toronto | C11: Ontario | D11: Canada | E11: North America | F11: Regional Office
A12: L11 | B12: Dubai | C12: Dubai | D12: United Arab Emirates | E12: Middle East | F12: Regional Office
... A14: L13 | B14: Mumbai | C14: Maharashtra | D14: India | E14: APAC | F14: Regional Office
A15: L14 | B15: Remote - Africa | E15: Africa | F15: Remote Hub
A16: L15 | B16: Remote - Global | E16: Global | F16: Remote Hub

Sheet Dim_Education
A1: EducationID | B1: EducationLevel | C1: EducationField
A2: E01 | B2: High School | C2: Business Administration
A3: E02 | B3: High School | C3: Computer Science
A4: E03 | B4: High School | C4: Engineering
A5: E04 | B5: High School | C5: Human Resources
A6: E05 | B6: High School | C6: Marketing
A7: E06 | B7: High School | C7: Finance & Accounting
A8: E07 | B8: High School | C8: Economics
A9: E08 | B9: High School | C9: Law
A10: E09 | B10: High School | C10: Communications
A11: E10 | B11: High School | C11: Other
A12: E11 | B12: Associate Degree | C12: Business Administration
... A51: E50 | B51: PhD / Doctorate | C51: Other

Sheet Dim_Date
A1: DateKey | B1: Date | C1: Year | D1: FiscalYear | E1: QuarterNumber | F1: Quarter | G1: MonthNumber | H1: MonthName | I1: MonthShort | J1: Day | K1: DayName | L1: WeekOfYear | M1: IsWeekend | N1: YearMonth
A2: 20180101 | B2: 2018-01-01 | C2: 2018 | D2: 2018 | E2: 1 | F2: Q1 | G2: 1 | H2: January | I2: Jan | J2: 1 | K2: Monday | L2: 1 | M2: =FALSE() -> FALSE | N2: 2018-01
A3: 20180102 | B3: 2018-01-02 | C3: 2018 | D3: 2018 | E3: 1 | F3: Q1 | G3: 1 | H3: January | I3: Jan | J3: 2 | K3: Tuesday | L3: 1 | M3: =FALSE() -> FALSE | N3: 2018-01
A4: 20180103 | B4: 2018-01-03 | C4: 2018 | D4: 2018 | E4: 1 | F4: Q1 | G4: 1 | H4: January | I4: Jan | J4: 3 | K4: Wednesday | L4: 1 | M4: =FALSE() -> FALSE | N4: 2018-01
A5: 20180104 | B5: 2018-01-04 | C5: 2018 | D5: 2018 | E5: 1 | F5: Q1 | G5: 1 | H5: January | I5: Jan | J5: 4 | K5: Thursday | L5: 1 | M5: =FALSE() -> FALSE | N5: 2018-01
A6: 20180105 | B6: 2018-01-05 | C6: 2018 | D6: 2018 | E6: 1 | F6: Q1 | G6: 1 | H6: January | I6: Jan | J6: 5 | K6: Friday | L6: 1 | M6: =FALSE() -> FALSE | N6: 2018-01
A7: 20180106 | B7: 2018-01-06 | C7: 2018 | D7: 2018 | E7: 1 | F7: Q1 | G7: 1 | H7: January | I7: Jan | J7: 6 | K7: Saturday | L7: 1 | M7: =TRUE() -> TRUE | N7: 2018-01
A8: 20180107 | B8: 2018-01-07 | C8: 2018 | D8: 2018 | E8: 1 | F8: Q1 | G8: 1 | H8: January | I8: Jan | J8: 7 | K8: Sunday | L8: 1 | M8: =TRUE() -> TRUE | N8: 2018-01
A9: 20180108 | B9: 2018-01-08 | C9: 2018 | D9: 2018 | E9: 1 | F9: Q1 | G9: 1 | H9: January | I9: Jan | J9: 8 | K9: Monday | L9: 2 | M9: =FALSE() -> FALSE | N9: 2018-01
A10: 20180109 | B10: 2018-01-09 | C10: 2018 | D10: 2018 | E10: 1 | F10: Q1 | G10: 1 | H10: January | I10: Jan | J10: 9 | K10: Tuesday | L10: 2 | M10: =FALSE() -> FALSE | N10: 2018-01
A11: 20180110 | B11: 2018-01-10 | C11: 2018 | D11: 2018 | E11: 1 | F11: Q1 | G11: 1 | H11: January | I11: Jan | J11: 10 | K11: Wednesday | L11: 2 | M11: =FALSE() -> FALSE | N11: 2018-01
A12: 20180111 | B12: 2018-01-11 | C12: 2018 | D12: 2018 | E12: 1 | F12: Q1 | G12: 1 | H12: January | I12: Jan | J12: 11 | K12: Thursday | L12: 2 | M12: =FALSE() -> FALSE | N12: 2018-01
A13: 20180112 | B13: 2018-01-12 | C13: 2018 | D13: 2018 | E13: 1 | F13: Q1 | G13: 1 | H13: January | I13: Jan | J13: 12 | K13: Friday | L13: 2 | M13: =FALSE() -> FALSE | N13: 2018-01
A14: 20180113 | B14: 2018-01-13 | C14: 2018 | D14: 2018 | E14: 1 | F14: Q1 | G14: 1 | H14: January | I14: Jan | J14: 13 | K14: Saturday | L14: 2 | M14: =TRUE() -> TRUE | N14: 2018-01
A15: 20180114 | B15: 2018-01-14 | C15: 2018 | D15: 2018 | E15: 1 | F15: Q1 | G15: 1 | H15: January | I15: Jan | J15: 14 | K15: Sunday | L15: 2 | M15: =TRUE() -> TRUE | N15: 2018-01
A16: 20180115 | B16: 2018-01-15 | C16: 2018 | D16: 2018 | E16: 1 | F16: Q1 | G16: 1 | H16: January | I16: Jan | J16: 15 | K16: Monday | L16: 3 | M16: =FALSE() -> FALSE | N16: 2018-01
A17: 20180116 | B17: 2018-01-16 | C17: 2018 | D17: 2018 | E17: 1 | F17: Q1 | G17: 1 | H17: January | I17: Jan | J17: 16 | K17: Tuesday | L17: 3 | M17: =FALSE() -> FALSE | N17: 2018-01
A18: 20180117 | B18: 2018-01-17 | C18: 2018 | D18: 2018 | E18: 1 | F18: Q1 | G18: 1 | H18: January | I18: Jan | J18: 17 | K18: Wednesday | L18: 3 | M18: =FALSE() -> FALSE | N18: 2018-01
A19: 20180118 | B19: 2018-01-18 | C19: 2018 | D19: 2018 | E19: 1 | F19: Q1 | G19: 1 | H19: January | I19: Jan | J19: 18 | K19: Thursday | L19: 3 | M19: =FALSE() -> FALSE | N19: 2018-01
A20: 20180119 | B20: 2018-01-19 | C20: 2018 | D20: 2018 | E20: 1 | F20: Q1 | G20: 1 | H20: January | I20: Jan | J20: 19 | K20: Friday | L20: 3 | M20: =FALSE() -> FALSE | N20: 2018-01
A21: 20180120 | B21: 2018-01-20 | C21: 2018 | D21: 2018 | E21: 1 | F21: Q1 | G21: 1 | H21: January | I21: Jan | J21: 20 | K21: Saturday | L21: 3 | M21: =TRUE() -> TRUE | N21: 2018-01
A22: 20180121 | B22: 2018-01-21 | C22: 2018 | D22: 2018 | E22: 1 | F22: Q1 | G22: 1 | H22: January | I22: Jan | J22: 21 | K22: Sunday | L22: 3 | M22: =TRUE() -> TRUE | N22: 2018-01
A23: 20180122 | B23: 2018-01-22 | C23: 2018 | D23: 2018 | E23: 1 | F23: Q1 | G23: 1 | H23: January | I23: Jan | J23: 22 | K23: Monday | L23: 4 | M23: =FALSE() -> FALSE | N23: 2018-01
A24: 20180123 | B24: 2018-01-23 | C24: 2018 | D24: 2018 | E24: 1 | F24: Q1 | G24: 1 | H24: January | I24: Jan | J24: 23 | K24: Tuesday | L24: 4 | M24: =FALSE() -> FALSE | N24: 2018-01
A25: 20180124 | B25: 2018-01-24 | C25: 2018 | D25: 2018 | E25: 1 | F25: Q1 | G25: 1 | H25: January | I25: Jan | J25: 24 | K25: Wednesday | L25: 4 | M25: =FALSE() -> FALSE | N25: 2018-01
A26: 20180125 | B26: 2018-01-25 | C26: 2018 | D26: 2018 | E26: 1 | F26: Q1 | G26: 1 | H26: January | I26: Jan | J26: 25 | K26: Thursday | L26: 4 | M26: =FALSE() -> FALSE | N26: 2018-01
A27: 20180126 | B27: 2018-01-26 | C27: 2018 | D27: 2018 | E27: 1 | F27: Q1 | G27: 1 | H27: January | I27: Jan | J27: 26 | K27: Friday | L27: 4 | M27: =FALSE() -> FALSE | N27: 2018-01
A28: 20180127 | B28: 2018-01-27 | C28: 2018 | D28: 2018 | E28: 1 | F28: Q1 | G28: 1 | H28: January | I28: Jan | J28: 27 | K28: Saturday | L28: 4 | M28: =TRUE() -> TRUE | N28: 2018-01
A29: 20180128 | B29: 2018-01-28 | C29: 2018 | D29: 2018 | E29: 1 | F29: Q1 | G29: 1 | H29: January | I29: Jan | J29: 28 | K29: Sunday | L29: 4 | M29: =TRUE() -> TRUE | N29: 2018-01
A30: 20180129 | B30: 2018-01-29 | C30: 2018 | D30: 2018 | E30: 1 | F30: Q1 | G30: 1 | H30: January | I30: Jan | J30: 29 | K30: Monday | L30: 5 | M30: =FALSE() -> FALSE | N30: 2018-01
A31: 20180130 | B31: 2018-01-30 | C31: 2018 | D31: 2018 | E31: 1 | F31: Q1 | G31: 1 | H31: January | I31: Jan | J31: 30 | K31: Tuesday | L31: 5 | M31: =FALSE() -> FALSE | N31: 2018-01
A32: 20180131 | B32: 2018-01-31 | C32: 2018 | D32: 2018 | E32: 1 | F32: Q1 | G32: 1 | H32: January | I32: Jan | J32: 31 | K32: Wednesday | L32: 5 | M32: =FALSE() -> FALSE | N32: 2018-01
A33: 20180201 | B33: 2018-02-01 | C33: 2018 | D33: 2018 | E33: 1 | F33: Q1 | G33: 2 | H33: February | I33: Feb | J33: 1 | K33: Thursday | L33: 5 | M33: =FALSE() -> FALSE | N33: 2018-02
A34: 20180202 | B34: 2018-02-02 | C34: 2018 | D34: 2018 | E34: 1 | F34: Q1 | G34: 2 | H34: February | I34: Feb | J34: 2 | K34: Friday | L34: 5 | M34: =FALSE() -> FALSE | N34: 2018-02
A35: 20180203 | B35: 2018-02-03 | C35: 2018 | D35: 2018 | E35: 1 | F35: Q1 | G35: 2 | H35: February | I35: Feb | J35: 3 | K35: Saturday | L35: 5 | M35: =TRUE() -> TRUE | N35: 2018-02
A36: 20180204 | B36: 2018-02-04 | C36: 2018 | D36: 2018 | E36: 1 | F36: Q1 | G36: 2 | H36: February | I36: Feb | J36: 4 | K36: Sunday | L36: 5 | M36: =TRUE() -> TRUE | N36: 2018-02
A37: 20180205 | B37: 2018-02-05 | C37: 2018 | D37: 2018 | E37: 1 | F37: Q1 | G37: 2 | H37: February | I37: Feb | J37: 5 | K37: Monday | L37: 6 | M37: =FALSE() -> FALSE | N37: 2018-02
A38: 20180206 | B38: 2018-02-06 | C38: 2018 | D38: 2018 | E38: 1 | F38: Q1 | G38: 2 | H38: February | I38: Feb | J38: 6 | K38: Tuesday | L38: 6 | M38: =FALSE() -> FALSE | N38: 2018-02
A39: 20180207 | B39: 2018-02-07 | C39: 2018 | D39: 2018 | E39: 1 | F39: Q1 | G39: 2 | H39: February | I39: Feb | J39: 7 | K39: Wednesday | L39: 6 | M39: =FALSE() -> FALSE | N39: 2018-02
A40: 20180208 | B40: 2018-02-08 | C40: 2018 | D40: 2018 | E40: 1 | F40: Q1 | G40: 2 | H40: February | I40: Feb | J40: 8 | K40: Thursday | L40: 6 | M40: =FALSE() -> FALSE | N40: 2018-02
...

Sheet Fact_PerformanceReviews
A1: ReviewID | B1: EmployeeID | C1: ReviewDate | D1: ReviewYear | E1: PerformanceRating | F1: EngagementScorePercent | G1: JobSatisfactionScore | H1: ManagerFeedbackScore | I1: GoalsAchievedPercent | J1: TrainingHoursCompleted | K1: PromotionRecommended
A2: REV00001 | B2: EMP0001 | C2: 2025-02-17 | D2: 2025 | E2: 4 | F2: 62 | G2: 3 | H2: 4 | I2: 58 | J2: 36 | K2: No
A3: REV00002 | B3: EMP0001 | C3: 2026-03-24 | D3: 2026 | E3: 1 | F3: 39 | G3: 4 | H3: 3 | I3: 73 | J3: 30 | K3: No
A4: REV00003 | B4: EMP0002 | C4: 2025-04-13 | D4: 2025 | E4: 2 | F4: 68 | G4: 3 | H4: 5 | I4: 79 | J4: 41 | K4: No
A5: REV00004 | B5: EMP0003 | C5: 2021-04-13 | D5: 2021 | E5: 2 | F5: 86 | G5: 3 | H5: 3 | I5: 74 | J5: 10 | K5: No
A6: REV00005 | B6: EMP0003 | C6: 2022-03-27 | D6: 2022 | E6: 2 | F6: 75 | G6: 2 | H6: 3 | I6: 53 | J6: 11 | K6: No
A7: REV00006 | B7: EMP0003 | C7: 2023-12-18 | D7: 2023 | E7: 3 | F7: 81 | G7: 4 | H7: 3 | I7: 94 | J7: 21 | K7: No
A8: REV00007 | B8: EMP0003 | C8: 2024-10-27 | D8: 2024 | E8: 4 | F8: 58 | G8: 3 | H8: 2 | I8: 91 | J8: 34 | K8: Yes
A9: REV00008 | B9: EMP0003 | C9: 2025-12-15 | D9: 2025 | E9: 4 | F9: 92 | G9: 3 | H9: 2 | I9: 109 | J9: 35 | K9: No
A10: REV00009 | B10: EMP0004 | C10: 2024-07-27 | D10: 2024 | E10: 3 | F10: 63 | G10: 2 | H10: 3 | I10: 88 | J10: 40 | K10: No
A11: REV00010 | B11: EMP0004 | C11: 2025-07-06 | D11: 2025 | E11: 4 | F11: 75 | G11: 2 | H11: 5 | I11: 78 | J11: 5 | K11: Yes
A12: REV00011 | B12: EMP0004 | C12: 2026-06-21 | D12: 2026 | E12: 2 | F12: 53 | G12: 3 | H12: 5 | I12: 94 | J12: 37 | K12: No
A13: REV00012 | B13: EMP0005 | C13: 2022-07-07 | D13: 2022 | E13: 3 | F13: 97 | G13: 4 | H13: 4 | I13: 74 | J13: 1 | K13: No
... A3174: REV03173 | B3174: EMP1000 | C3174: 2025-02-16 | D3174: 2025 | E3174: 1 | F3174: 45 | G3174: 2 | H3174: 3 | I3174: 98 | J3174: 37 | K3174: No
