Workbook

Sheet README
B2: GEREGU POWER ENERGY PLC — TABLEAU DASHBOARD TRAINING DATASET
B3: Simulated multi-department dataset for Tableau training purposes
B5: Prepared by: Kajola Gbenga
B6: Data Scientist & AI Engineer
B9: Sheet Name | C9: Purpose | D9: Key Columns Linking to Other Sheets
B10: Dim_Date | C10: Central date dimension - connect to every transactional sheet's Date field for time intelligence. | D10: Date
B11: Dim_Department | C11: Department master list with mandate and head of department. | D11: Department_ID, Department_Name, Head_Employee_ID
B12: Dim_Employee | C12: Employee master (HR) - connects to every other sheet through Employee_ID. | D12: Employee_ID, Department
B13: Operations | C13: Daily plant/unit generation performance. | D13: Employee_ID, Date
B14: Legal | C14: Contracts, litigation and regulatory case tracking. | D14: Employee_ID, Date_Opened, Department_Linked
B15: Supply_Chain | C15: Procurement and vendor purchase orders. | D15: Employee_ID, Date
B16: Admin | C16: Facilities, assets, travel and fleet requests. | D16: Employee_ID, Date
B17: Customer_Service | C17: DisCo/off-taker ticket and complaints log. | D17: Employee_ID, Date
B18: IT | C18: Systems and SCADA support ticket log. | D18: Employee_ID, Date
B19: Accounts_Finance | C19: Revenue, opex and capex transactions vs budget. | D19: Employee_ID, Date, Department_Linked
B20: Human_Resources | C20: Leave, training, appraisal and disciplinary records. | D20: Employee_ID, Date, Department
... B22: Risk_Mgmt_Compliance | C22: Enterprise risk register with likelihood x impact scoring. | D22: Employee_ID, Date_Identified, Department_Linked
B25: Color legend:
B26: Blue text = linking/key column (e.g. Employee_ID)
B27: Green text = formula pulling data from another sheet (e.g. Employee_Name via INDEX/MATCH)
B28: Black text = raw / hardcoded source data entered for the simulation
B30: How to use this workbook in Tableau:
B31: 1. Connect Tableau to this Excel file (Data > Connect to Data > Microsoft Excel).
B32: 2. Drag Dim_Employee and Dim_Department onto the canvas, then add each transactional sheet.
B33: 3. Build relationships (not physical joins) using Employee_ID as the linking field, and Date to Dim_Date's Date field.
B34: 4. This keeps each department's grain intact while allowing cross-department analysis in one data source.

Sheet Dim_Date
A1: Date | B1: Year | C1: Quarter | D1: Month_No | E1: Month_Name | F1: Week_No | G1: Day_Name | H1: Is_Weekend
A2: 45658 | B2: 2025 | C2: Q1 | D2: 1 | E2: January | F2: 1 | G2: Wednesday | H2: No
A3: 45659 | B3: 2025 | C3: Q1 | D3: 1 | E3: January | F3: 1 | G3: Thursday | H3: No
A4: 45660 | B4: 2025 | C4: Q1 | D4: 1 | E4: January | F4: 1 | G4: Friday | H4: No
A5: 45661 | B5: 2025 | C5: Q1 | D5: 1 | E5: January | F5: 1 | G5: Saturday | H5: Yes
A6: 45662 | B6: 2025 | C6: Q1 | D6: 1 | E6: January | F6: 1 | G6: Sunday | H6: Yes
A7: 45663 | B7: 2025 | C7: Q1 | D7: 1 | E7: January | F7: 2 | G7: Monday | H7: No
A8: 45664 | B8: 2025 | C8: Q1 | D8: 1 | E8: January | F8: 2 | G8: Tuesday | H8: No
A9: 45665 | B9: 2025 | C9: Q1 | D9: 1 | E9: January | F9: 2 | G9: Wednesday | H9: No
A10: 45666 | B10: 2025 | C10: Q1 | D10: 1 | E10: January | F10: 2 | G10: Thursday | H10: No
A11: 45667 | B11: 2025 | C11: Q1 | D11: 1 | E11: January | F11: 2 | G11: Friday | H11: No
A12: 45668 | B12: 2025 | C12: Q1 | D12: 1 | E12: January | F12: 2 | G12: Saturday | H12: Yes
A13: 45669 | B13: 2025 | C13: Q1 | D13: 1 | E13: January | F13: 2 | G13: Sunday | H13: Yes
... A366: 46022 | B366: 2025 | C366: Q4 | D366: 12 | E366: December | F366: 1 | G366: Wednesday | H366: No

Sheet Dim_Department
A1: Department_ID | B1: Department_Name | C1: Location | D1: Department_Mandate | E1: Head_Employee_ID
A2: DPT01 | B2: Operations | C2: Kogi Plant Site | D2: Power generation and plant performance | E2: EMP0001
A3: DPT02 | B3: Legal | C3: Head Office - Abuja | D3: Contracts, litigation and regulatory affairs | E3: EMP0017
A4: DPT03 | B4: Supply Chain | C4: Head Office - Abuja | D4: Procurement, vendor and inventory management | E4: EMP0022
A5: DPT04 | B5: Admin | C5: Kogi Plant Site | D5: Facilities, assets and general administration | E5: EMP0030
A6: DPT05 | B6: Customer Service | C6: Head Office - Abuja | D6: DisCo and off-taker relationship management | E6: EMP0036
A7: DPT06 | B7: IT | C7: Head Office - Abuja | D7: Systems, SCADA support and infrastructure | E7: EMP0043
A8: DPT07 | B8: Accounts and Finance | C8: Head Office - Abuja | D8: Revenue, expenditure and financial reporting | E8: EMP0050
A9: DPT08 | B9: Human Resources | C9: Head Office - Abuja | D9: Recruitment, welfare, training and payroll | E9: EMP0058
A10: DPT09 | B10: Internal Control | C10: Head Office - Abuja | D10: Internal audit and process assurance | E10: EMP0065
A11: DPT10 | B11: Risk Management and Compliance | C11: Head Office - Abuja | D11: Enterprise risk and regulatory compliance | E11: EMP0070

Sheet Dim_Employee
A1: Employee_ID | B1: Employee_Name | C1: Department | D1: Job_Title | E1: Gender | F1: Date_Hired | G1: Employment_Status | H1: Work_Email | I1: Phone_Number
A2: EMP0001 | B2: Ngozi Okafor | C2: Operations | D2: Plant Manager | E2: Female | F2: 44625 | G2: Active | H2: ngozi.okafor@geregupower.com | I2: 08023756669
A3: EMP0002 | B3: Abdullahi Adeyemi | C3: Operations | D3: Shift Engineer | E3: Female | F3: 45498 | G3: Active | H3: abdullahi.adeyemi@geregupower.com | I3: 08039345092
A4: EMP0003 | B4: Olamide Sani | C4: Operations | D4: Turbine Technician | E4: Male | F4: 43330 | G4: Active | H4: olamide.sani@geregupower.com | I4: 08097226012
A5: EMP0004 | B5: Abdullahi Aliyu | C5: Operations | D5: Control Room Operator | E5: Male | F5: 43789 | G5: Active | H5: abdullahi.aliyu@geregupower.com | I5: 08010872248
A6: EMP0005 | B6: Kelechi Ojo | C6: Operations | D6: HSE Officer | E6: Female | F6: 44235 | G6: Active | H6: kelechi.ojo@geregupower.com | I6: 08038898923
A7: EMP0006 | B7: Halima Nwosu | C7: Operations | D7: Maintenance Engineer | E7: Male | F7: 44072 | G7: Active | H7: halima.nwosu@geregupower.com | I7: 08056164955
A8: EMP0007 | B8: Emmanuel Yakubu | C8: Operations | D8: Plant Manager | E8: Male | F8: 42640 | G8: Active | H8: emmanuel.yakubu@geregupower.com | I8: 08026753883
A9: EMP0008 | B9: Musa Adeyemi | C9: Operations | D9: Shift Engineer | E9: Female | F9: 42231 | G9: Active | H9: musa.adeyemi@geregupower.com | I9: 08058537831
A10: EMP0009 | B10: Kingsley Okonkwo | C10: Operations | D10: Turbine Technician | E10: Male | F10: 45441 | G10: Active | H10: kingsley.okonkwo@geregupower.com | I10: 08048840994
A11: EMP0010 | B11: Amaka Bakare | C11: Operations | D11: Control Room Operator | E11: Male | F11: 42079 | G11: Active | H11: amaka.bakare@geregupower.com | I11: 08047308985
A12: EMP0011 | B12: Titilayo Danjuma | C12: Operations | D12: HSE Officer | E12: Female | F12: 44962 | G12: Active | H12: titilayo.danjuma@geregupower.com | I12: 08038119557
A13: EMP0012 | B13: Uche Ojo | C13: Operations | D13: Maintenance Engineer | E13: Male | F13: 43133 | G13: Active | H13: uche.ojo@geregupower.com | I13: 08081691040
... A76: EMP0075 | B76: Halima Okafor | C76: Risk Management and Compliance | D76: Risk Analyst | E76: Male | F76: 42036 | G76: Resigned | H76: halima.okafor@geregupower.com | I76: 08033966966

Sheet Operations
A1: Record_ID | B1: Date | C1: Plant_Unit | D1: Employee_ID | E1: Employee_Name | F1: Shift | G1: Power_Generated_MWh | H1: Planned_Output_MWh | I1: Availability_Percent | J1: Downtime_Hours | K1: Downtime_Reason | L1: Fuel_Type | M1: Fuel_Consumed_MMscf | N1: Turbine_Temperature_C | O1: Maintenance_Status
A2: OPS00001 | B2: 45932 | C2: GT1 | D2: EMP0011 | E2: =IFERROR(INDEX(Dim_Employee!$B$2:$B$76,MATCH(D2,Dim_Employee!$A$2:$A$76,0)),"") -> Titilayo Danjuma | F2: Afternoon | G2: 99.3 | H2: 118.4 | I2: =ROUND(G2/H2*100,1) -> 83.9 | J2: 2.1 | K2: Scheduled Maintenance | L2: Natural Gas | M2: 22.48 | N2: 510.1 | O2: Normal
A3: OPS00002 | B3: 45688 | C3: GT1 | D3: EMP0014 | E3: =IFERROR(INDEX(Dim_Employee!$B$2:$B$76,MATCH(D3,Dim_Employee!$A$2:$A$76,0)),"") -> Peace Balogun | F3: Morning | G3: 81.2 | H3: 102.5 | I3: =ROUND(G3/H3*100,1) -> 79.2 | J3: 4.5 | K3: Gas Supply Shortage | L3: Natural Gas | M3: 17.32 | N3: 488.7 | O3: Scheduled
A4: OPS00003 | B4: 45806 | C4: ST1 | D4: EMP0002 | E4: =IFERROR(INDEX(Dim_Employee!$B$2:$B$76,MATCH(D4,Dim_Employee!$A$2:$A$76,0)),"") -> Abdullahi Adeyemi | F4: Morning | G4: 87.6 | H4: 119.3 | I4: =ROUND(G4/H4*100,1) -> 73.4 | J4: 8.6 | K4: Scheduled Maintenance | L4: Natural Gas | M4: 18.64 | N4: 558.4 | O4: Under Inspection
A5: OPS00004 | B5: 45938 | C5: GT1 | D5: EMP0004 | E5: =IFERROR(INDEX(Dim_Employee!$B$2:$B$76,MATCH(D5,Dim_Employee!$A$2:$A$76,0)),"") -> Abdullahi Aliyu | F5: Night | G5: 97.9 | H5: 107.4 | I5: =ROUND(G5/H5*100,1) -> 91.2 | J5: 1.7 | K5: None | L5: Natural Gas | M5: 19.41 | N5: 575.3 | O5: Scheduled
A6: OPS00005 | B6: 45785 | C6: GT2 | D6: EMP0011 | E6: =IFERROR(INDEX(Dim_Employee!$B$2:$B$76,MATCH(D6,Dim_Employee!$A$2:$A$76,0)),"") -> Titilayo Danjuma | F6: Night | G6: 103.7 | H6: 104 | I6: =ROUND(G6/H6*100,1) -> 99.7 | J6: 0.1 | K6: Grid Instability | L6: Natural Gas | M6: 20.04 | N6: 522 | O6: Scheduled
A7: OPS00006 | B7: 45718 | C7: ST1 | D7: EMP0011 | E7: =IFERROR(INDEX(Dim_Employee!$B$2:$B$76,MATCH(D7,Dim_Employee!$A$2:$A$76,0)),"") -> Titilayo Danjuma | F7: Morning | G7: 90.2 | H7: 111.9 | I7: =ROUND(G7/H7*100,1) -> 80.6 | J7: 6.4 | K7: Grid Instability | L7: Natural Gas | M7: 17.69 | N7: 548.5 | O7: Normal
A8: OPS00007 | B8: 45818 | C8: GT3 | D8: EMP0003 | E8: =IFERROR(INDEX(Dim_Employee!$B$2:$B$76,MATCH(D8,Dim_Employee!$A$2:$A$76,0)),"") -> Olamide Sani | F8: Night | G8: 100.7 | H8: 112.9 | I8: =ROUND(G8/H8*100,1) -> 89.2 | J8: 3.4 | K8: None | L8: Natural Gas | M8: 21.13 | N8: 591.6 | O8: Normal
A9: OPS00008 | B9: 45689 | C9: GT3 | D9: EMP0003 | E9: =IFERROR(INDEX(Dim_Employee!$B$2:$B$76,MATCH(D9,Dim_Employee!$A$2:$A$76,0)),"") -> Olamide Sani | F9: Night | G9: 102 | H9: 118.3 | I9: =ROUND(G9/H9*100,1) -> 86.2 | J9: 3.8 | K9: Scheduled Maintenance | L9: Natural Gas | M9: 22.16 | N9: 542.4 | O9: Scheduled
A10: OPS00009 | B10: 45717 | C10: ST1 | D10: EMP0012 | E10: =IFERROR(INDEX(Dim_Employee!$B$2:$B$76,MATCH(D10,Dim_Employee!$A$2:$A$76,0)),"") -> Uche Ojo | F10: Morning | G10: 77.9 | H10: 90.7 | I10: =ROUND(G10/H10*100,1) -> 85.9 | J10: 1.7 | K10: None | L10: Natural Gas | M10: 15.7 | N10: 583.4 | O10: Scheduled
A11: OPS00010 | B11: 45863 | C11: GT3 | D11: EMP0013 | E11: =IFERROR(INDEX(Dim_Employee!$B$2:$B$76,MATCH(D11,Dim_Employee!$A$2:$A$76,0)),"") -> Chukwudi Eze | F11: Morning | G11: 102.1 | H11: 117.5 | I11: =ROUND(G11/H11*100,1) -> 86.9 | J11: 2.1 | K11: Grid Instability | L11: Natural Gas | M11: 22.93 | N11: 519 | O11: Scheduled
A12: OPS00011 | B12: 45700 | C12: GT2 | D12: EMP0012 | E12: =IFERROR(INDEX(Dim_Employee!$B$2:$B$76,MATCH(D12,Dim_Employee!$A$2:$A$76,0)),"") -> Uche Ojo | F12: Morning | G12: 92.2 | H12: 110.5 | I12: =ROUND(G12/H12*100,1) -> 83.4 | J12: 2.7 | K12: None | L12: Natural Gas | M12: 18.38 | N12: 547.9 | O12: Under Inspection
A13: OPS00012 | B13: 45970 | C13: GT3 | D13: EMP0009 | E13: =IFERROR(INDEX(Dim_Employee!$B$2:$B$76,MATCH(D13,Dim_Employee!$A$2:$A$76,0)),"") -> Kingsley Okonkwo | F13: Morning | G13: 75.2 | H13: 98.5 | I13: =ROUND(G13/H13*100,1) -> 76.3 | J13: 4.8 | K13: Gas Supply Shortage | L13: Natural Gas | M13: 15.84 | N13: 566.5 | O13: Normal
... A221: OPS00220 | B221: 45855 | C221: GT3 | D221: EMP0013 | E221: =IFERROR(INDEX(Dim_Employee!$B$2:$B$76,MATCH(D221,Dim_Employee!$A$2:$A$76,0)),"") -> Chukwudi Eze | F221: Afternoon | G221: 80.6 | H221: 106.8 | I221: =ROUND(G221/H221*100,1) -> 75.5 | J221: 5.4 | K221: Gas Supply Shortage | L221: Natural Gas | M221: 18.41 | N221: 539.1 | O221: Under Repair

Sheet Legal
A1: Case_ID | B1: Date_Opened | C1: Employee_ID | D1: Employee_Name | E1: Department_Linked | F1: Case_Type | G1: Counterparty | H1: Risk_Level | I1: Case_Status | J1: Resolution_Date | K1: Cost_Incurred_NGN
A2: LEG0001 | B2: 45783 | C2: EMP0021 | D2: =IFERROR(INDEX(Dim_Employee!$B$2:$B$76,MATCH(C2,Dim_Employee!$A$2:$A$76,0)),"") -> Tunde Nnamdi | E2: Supply Chain | F2: Compliance Advisory | G2: Local Vendor Ltd | H2: Low | I2: Under Review | K2: 2206103.4
A3: LEG0002 | B3: 45998 | C3: EMP0019 | D3: =IFERROR(INDEX(Dim_Employee!$B$2:$B$76,MATCH(C3,Dim_Employee!$A$2:$A$76,0)),"") -> Yusuf Sani | E3: Admin | F3: Litigation | G3: Distribution Company - Abuja Disco | H3: Medium | I3: Open | K3: 508524.96
A4: LEG0003 | B4: 45936 | C4: EMP0019 | D4: =IFERROR(INDEX(Dim_Employee!$B$2:$B$76,MATCH(C4,Dim_Employee!$A$2:$A$76,0)),"") -> Yusuf Sani | E4: Accounts and Finance | F4: Compliance Advisory | G4: Distribution Company - Abuja Disco | H4: Low | I4: Closed | J4: 46017 | K4: 1796947.4
A5: LEG0004 | B5: 45850 | C5: EMP0020 | D5: =IFERROR(INDEX(Dim_Employee!$B$2:$B$76,MATCH(C5,Dim_Employee!$A$2:$A$76,0)),"") -> Aisha Danjuma | E5: Accounts and Finance | F5: Land/Right-of-Way | G5: Distribution Company - Abuja Disco | H5: Low | I5: Closed | J5: 45898 | K5: 2290826.2
A6: LEG0005 | B6: 46019 | C6: EMP0018 | D6: =IFERROR(INDEX(Dim_Employee!$B$2:$B$76,MATCH(C6,Dim_Employee!$A$2:$A$76,0)),"") -> Abdullahi Yakubu | E6: Human Resources | F6: Compliance Advisory | G6: NERC | H6: Medium | I6: Pending Court Date | K6: 2050545.6
A7: LEG0006 | B7: 45766 | C7: EMP0021 | D7: =IFERROR(INDEX(Dim_Employee!$B$2:$B$76,MATCH(C7,Dim_Employee!$A$2:$A$76,0)),"") -> Tunde Nnamdi | E7: Operations | F7: Land/Right-of-Way | G7: NBET | H7: Medium | I7: Closed | J7: 45872 | K7: 1388525.2
A8: LEG0007 | B8: 45672 | C8: EMP0020 | D8: =IFERROR(INDEX(Dim_Employee!$B$2:$B$76,MATCH(C8,Dim_Employee!$A$2:$A$76,0)),"") -> Aisha Danjuma | E8: Operations | F8: Compliance Advisory | G8: NBET | H8: Medium | I8: Closed | J8: 45721 | K8: 3891882.5
A9: LEG0008 | B9: 45822 | C9: EMP0018 | D9: =IFERROR(INDEX(Dim_Employee!$B$2:$B$76,MATCH(C9,Dim_Employee!$A$2:$A$76,0)),"") -> Abdullahi Yakubu | E9: Operations | F9: Contract Review | G9: Insurance Underwriter | H9: High | I9: Closed | J9: 45916 | K9: 4035642.7
A10: LEG0009 | B10: 45756 | C10: EMP0019 | D10: =IFERROR(INDEX(Dim_Employee!$B$2:$B$76,MATCH(C10,Dim_Employee!$A$2:$A$76,0)),"") -> Yusuf Sani | E10: Customer Service | F10: Regulatory Filing | G10: NBET | H10: Low | I10: Open | K10: 674356.25
A11: LEG0010 | B11: 45802 | C11: EMP0020 | D11: =IFERROR(INDEX(Dim_Employee!$B$2:$B$76,MATCH(C11,Dim_Employee!$A$2:$A$76,0)),"") -> Aisha Danjuma | E11: Accounts and Finance | F11: Compliance Advisory | G11: Distribution Company - Ikeja Disco | H11: High | I11: Pending Court Date | K11: 923147.5
A12: LEG0011 | B12: 46005 | C12: EMP0019 | D12: =IFERROR(INDEX(Dim_Employee!$B$2:$B$76,MATCH(C12,Dim_Employee!$A$2:$A$76,0)),"") -> Yusuf Sani | E12: Accounts and Finance | F12: Contract Review | G12: Community Association | H12: Low | I12: Pending Court Date | K12: 4241235.8
A13: LEG0012 | B13: 45979 | C13: EMP0019 | D13: =IFERROR(INDEX(Dim_Employee!$B$2:$B$76,MATCH(C13,Dim_Employee!$A$2:$A$76,0)),"") -> Yusuf Sani | E13: Supply Chain | F13: Regulatory Filing | G13: NBET | H13: Low | I13: Open | K13: 3064138
A14: LEG0013 | B14: 46022 | C14: EMP0018 | D14: =IFERROR(INDEX(Dim_Employee!$B$2:$B$76,MATCH(C14,Dim_Employee!$A$2:$A$76,0)),"") -> Abdullahi Yakubu | E14: Accounts and Finance | F14: Contract Review | G14: Distribution Company - Ikeja Disco | H14: Medium | I14: Open | K14: 3796950.5
A15: LEG0014 | B15: 45852 | C15: EMP0018 | D15: =IFERROR(INDEX(Dim_Employee!$B$2:$B$76,MATCH(C15,Dim_Employee!$A$2:$A$76,0)),"") -> Abdullahi Yakubu | E15: Human Resources | F15: Regulatory Filing | G15: Distribution Company - Ikeja Disco | H15: Medium | I15: Open | K15: 1176892.1
A16: LEG0015 | B16: 45924 | C16: EMP0020 | D16: =IFERROR(INDEX(Dim_Employee!$B$2:$B$76,MATCH(C16,Dim_Employee!$A$2:$A$76,0)),"") -> Aisha Danjuma | E16: Accounts and Finance | F16: Land/Right-of-Way | G16: NERC | H16: High | I16: Pending Court Date | K16: 603767
A17: LEG0016 | B17: 45679 | C17: EMP0019 | D17: =IFERROR(INDEX(Dim_Employee!$B$2:$B$76,MATCH(C17,Dim_Employee!$A$2:$A$76,0)),"") -> Yusuf Sani | E17: Supply Chain | F17: Contract Review | G17: TCN | H17: Medium | I17: Open | K17: 1090188.9
A18: LEG0017 | B18: 45702 | C18: EMP0019 | D18: =IFERROR(INDEX(Dim_Employee!$B$2:$B$76,MATCH(C18,Dim_Employee!$A$2:$A$76,0)),"") -> Yusuf Sani | E18: Customer Service | F18: Compliance Advisory | G18: Distribution Company - Abuja Disco | H18: Low | I18: Under Review | K18: 495171.24
A19: LEG0018 | B19: 45884 | C19: EMP0020 | D19: =IFERROR(INDEX(Dim_Employee!$B$2:$B$76,MATCH(C19,Dim_Employee!$A$2:$A$76,0)),"") -> Aisha Danjuma | E19: Customer Service | F19: Land/Right-of-Way | G19: Community Association | H19: Medium | I19: Pending Court Date | K19: 3399110.7
A20: LEG0019 | B20: 45877 | C20: EMP0018 | D20: =IFERROR(INDEX(Dim_Employee!$B$2:$B$76,MATCH(C20,Dim_Employee!$A$2:$A$76,0)),"") -> Abdullahi Yakubu | E20: Supply Chain | F20: Contract Review | G20: Insurance Underwriter | H20: Low | I20: Closed | J20: 45949 | K20: 2754697.2
A21: LEG0020 | B21: 45936 | C21: EMP0018 | D21: =IFERROR(INDEX(Dim_Employee!$B$2:$B$76,MATCH(C21,Dim_Employee!$A$2:$A$76,0)),"") -> Abdullahi Yakubu | E21: Supply Chain | F21: Contract Review | G21: Distribution Company - Ikeja Disco | H21: Low | I21: Pending Court Date | K21: 2087608.1
A22: LEG0021 | B22: 45983 | C22: EMP0018 | D22: =IFERROR(INDEX(Dim_Employee!$B$2:$B$76,MATCH(C22,Dim_Employee!$A$2:$A$76,0)),"") -> Abdullahi Yakubu | E22: Supply Chain | F22: Litigation | G22: Community Association | H22: Medium | I22: Pending Court Date | K22: 1227469.6
A23: LEG0022 | B23: 45661 | C23: EMP0018 | D23: =IFERROR(INDEX(Dim_Employee!$B$2:$B$76,MATCH(C23,Dim_Employee!$A$2:$A$76,0)),"") -> Abdullahi Yakubu | E23: Supply Chain | F23: Regulatory Filing | G23: Local Vendor Ltd | H23: Low | I23: Under Review | K23: 3553190.9
A24: LEG0023 | B24: 45946 | C24: EMP0021 | D24: =IFERROR(INDEX(Dim_Employee!$B$2:$B$76,MATCH(C24,Dim_Employee!$A$2:$A$76,0)),"") -> Tunde Nnamdi | E24: Customer Service | F24: Contract Review | G24: Insurance Underwriter | H24: Medium | I24: Closed | J24: 45998 | K24: 4709023.5
A25: LEG0024 | B25: 45964 | C25: EMP0018 | D25: =IFERROR(INDEX(Dim_Employee!$B$2:$B$76,MATCH(C25,Dim_Employee!$A$2:$A$76,0)),"") -> Abdullahi Yakubu | E25: Accounts and Finance | F25: Litigation | G25: NBET | H25: Medium | I25: Under Review | K25: 111237.96
A26: LEG0025 | B26: 45763 | C26: EMP0020 | D26: =IFERROR(INDEX(Dim_Employee!$B$2:$B$76,MATCH(C26,Dim_Employee!$A$2:$A$76,0)),"") -> Aisha Danjuma | E26: Operations | F26: Regulatory Filing | G26: Local Vendor Ltd | H26: Low | I26: Open | K26: 3523038
A27: LEG0026 | B27: 45715 | C27: EMP0020 | D27: =IFERROR(INDEX(Dim_Employee!$B$2:$B$76,MATCH(C27,Dim_Employee!$A$2:$A$76,0)),"") -> Aisha Danjuma | E27: Accounts and Finance | F27: Compliance Advisory | G27: NERC | H27: Low | I27: Closed | J27: 45766 | K27: 2809781.7
A28: LEG0027 | B28: 45663 | C28: EMP0017 | D28: =IFERROR(INDEX(Dim_Employee!$B$2:$B$76,MATCH(C28,Dim_Employee!$A$2:$A$76,0)),"") -> Titilayo Abubakar | E28: Accounts and Finance | F28: Contract Review | G28: NERC | H28: High | I28: Under Review | K28: 2840084.3
A29: LEG0028 | B29: 45988 | C29: EMP0017 | D29: =IFERROR(INDEX(Dim_Employee!$B$2:$B$76,MATCH(C29,Dim_Employee!$A$2:$A$76,0)),"") -> Titilayo Abubakar | E29: Accounts and Finance | F29: Compliance Advisory | G29: Distribution Company - Abuja Disco | H29: Medium | I29: Under Review | K29: 1642974.5
A30: LEG0029 | B30: 45704 | C30: EMP0019 | D30: =IFERROR(INDEX(Dim_Employee!$B$2:$B$76,MATCH(C30,Dim_Employee!$A$2:$A$76,0)),"") -> Yusuf Sani | E30: Customer Service | F30: Land/Right-of-Way | G30: Local Vendor Ltd | H30: Medium | I30: Pending Court Date | K30: 436816.78
A31: LEG0030 | B31: 45670 | C31: EMP0017 | D31: =IFERROR(INDEX(Dim_Employee!$B$2:$B$76,MATCH(C31,Dim_Employee!$A$2:$A$76,0)),"") -> Titilayo Abubakar | E31: Supply Chain | F31: Regulatory Filing | G31: NERC | H31: Low | I31: Under Review | K31: 3208599.4
A32: LEG0031 | B32: 45710 | C32: EMP0018 | D32: =IFERROR(INDEX(Dim_Employee!$B$2:$B$76,MATCH(C32,Dim_Employee!$A$2:$A$76,0)),"") -> Abdullahi Yakubu | E32: Customer Service | F32: Land/Right-of-Way | G32: NERC | H32: Low | I32: Pending Court Date | K32: 3254159.9
A33: LEG0032 | B33: 45821 | C33: EMP0019 | D33: =IFERROR(INDEX(Dim_Employee!$B$2:$B$76,MATCH(C33,Dim_Employee!$A$2:$A$76,0)),"") -> Yusuf Sani | E33: Supply Chain | F33: Land/Right-of-Way | G33: NERC | H33: High | I33: Closed | J33: 45878 | K33: 1305072.2
A34: LEG0033 | B34: 45679 | C34: EMP0017 | D34: =IFERROR(INDEX(Dim_Employee!$B$2:$B$76,MATCH(C34,Dim_Employee!$A$2:$A$76,0)),"") -> Titilayo Abubakar | E34: Human Resources | F34: Compliance Advisory | G34: TCN | H34: High | I34: Open | K34: 2497180.2
A35: LEG0034 | B35: 45738 | C35: EMP0020 | D35: =IFERROR(INDEX(Dim_Employee!$B$2:$B$76,MATCH(C35,Dim_Employee!$A$2:$A$76,0)),"") -> Aisha Danjuma | E35: Human Resources | F35: Land/Right-of-Way | G35: NBET | H35: Low | I35: Pending Court Date | K35: 1176121.4
A36: LEG0035 | B36: 45884 | C36: EMP0018 | D36: =IFERROR(INDEX(Dim_Employee!$B$2:$B$76,MATCH(C36,Dim_Employee!$A$2:$A$76,0)),"") -> Abdullahi Yakubu | E36: Operations | F36: Contract Review | G36: Community Association | H36: Medium | I36: Under Review | K36: 1130462.6
A37: LEG0036 | B37: 45659 | C37: EMP0019 | D37: =IFERROR(INDEX(Dim_Employee!$B$2:$B$76,MATCH(C37,Dim_Employee!$A$2:$A$76,0)),"") -> Yusuf Sani | E37: Human Resources | F37: Land/Right-of-Way | G37: State Government - Kogi | H37: Low | I37: Open | K37: 406371.35
A38: LEG0037 | B38: 45921 | C38: EMP0017 | D38: =IFERROR(INDEX(Dim_Employee!$B$2:$B$76,MATCH(C38,Dim_Employee!$A$2:$A$76,0)),"") -> Titilayo Abubakar | E38: Admin | F38: Contract Review | G38: Community Association | H38: Low | I38: Under Review | K38: 4782239.7
A39: LEG0038 | B39: 45742 | C39: EMP0018 | D39: =IFERROR(INDEX(Dim_Employee!$B$2:$B$76,MATCH(C39,Dim_Employee!$A$2:$A$76,0)),"") -> Abdullahi Yakubu | E39: Admin | F39: Contract Review | G39: Community Association | H39: High | I39: Under Review | K39: 3392544.3
A40: LEG0039 | B40: 45758 | C40: EMP0021 | D40: =IFERROR(INDEX(Dim_Employee!$B$2:$B$76,MATCH(C40,Dim_Employee!$A$2:$A$76,0)),"") -> Tunde Nnamdi | E40: Operations | F40: Land/Right-of-Way | G40: NERC | H40: Medium | I40: Under Review | K40: 2170456.5
...

Sheet Supply_Chain
A1: PO_ID | B1: Date | C1: Employee_ID | D1: Employee_Name | E1: Vendor_Name | F1: Item_Category | G1: Item_Description | H1: Quantity | I1: Unit_Cost_NGN | J1: Total_Cost_NGN | K1: Lead_Time_Days | L1: Delivery_Status | M1: Approval_Status
A2: PO00001 | B2: 45727 | C2: EMP0024 | D2: =IFERROR(INDEX(Dim_Employee!$B$2:$B$76,MATCH(C2,Dim_Employee!$A$2:$A$76,0)),"") -> Titilayo Okafor | E2: Total Energies Nigeria | F2: Safety Equipment | G2: PPE Kits | H2: 197 | I2: 228283.84 | J2: =H2*I2 -> 44971916 | K2: 7 | L2: Pending Dispatch | M2: Approved
A3: PO00002 | B3: 45970 | C3: EMP0029 | D3: =IFERROR(INDEX(Dim_Employee!$B$2:$B$76,MATCH(C3,Dim_Employee!$A$2:$A$76,0)),"") -> Amaka Usman | E3: Cummins West Africa | F3: Fuel | G3: Natural Gas Supply Top-up | H3: 42 | I3: 272823.31 | J3: =H3*I3 -> 11458579 | K3: 39 | L3: Delivered | M3: Approved
A4: PO00003 | B4: 45882 | C4: EMP0027 | D4: =IFERROR(INDEX(Dim_Employee!$B$2:$B$76,MATCH(C4,Dim_Employee!$A$2:$A$76,0)),"") -> Adaeze Onyeka | E4: GE Power Services | F4: Spare Parts | G4: Control Valve | H4: 200 | I4: 658188.28 | J4: =H4*I4 -> 131637656 | K4: 57 | L4: In Transit | M4: Pending Approval
A5: PO00004 | B5: 45662 | C5: EMP0022 | D5: =IFERROR(INDEX(Dim_Employee!$B$2:$B$76,MATCH(C5,Dim_Employee!$A$2:$A$76,0)),"") -> Zainab Igwe | E5: GE Power Services | F5: Spare Parts | G5: Bearing Assembly | H5: 39 | I5: 828224.47 | J5: =H5*I5 -> 32300754 | K5: 11 | L5: Pending Dispatch | M5: Approved
A6: PO00005 | B6: 45870 | C6: EMP0024 | D6: =IFERROR(INDEX(Dim_Employee!$B$2:$B$76,MATCH(C6,Dim_Employee!$A$2:$A$76,0)),"") -> Titilayo Okafor | E6: Safety First Equipment Ltd | F6: Safety Equipment | G6: Gas Detectors | H6: 175 | I6: 338502.11 | J6: =H6*I6 -> 59237869 | K6: 60 | L6: Delayed | M6: Pending Approval
A7: PO00006 | B7: 45979 | C7: EMP0022 | D7: =IFERROR(INDEX(Dim_Employee!$B$2:$B$76,MATCH(C7,Dim_Employee!$A$2:$A$76,0)),"") -> Zainab Igwe | E7: Dantata Engineering Ltd | F7: IT Hardware | G7: Network Switch | H7: 61 | I7: 172369.21 | J7: =H7*I7 -> 10514522 | K7: 10 | L7: In Transit | M7: Rejected
A8: PO00007 | B8: 45682 | C8: EMP0028 | D8: =IFERROR(INDEX(Dim_Employee!$B$2:$B$76,MATCH(C8,Dim_Employee!$A$2:$A$76,0)),"") -> Blessing Balogun | E8: Safety First Equipment Ltd | F8: Office Supplies | G8: Stationery Bundle | H8: 27 | I8: 619635.93 | J8: =H8*I8 -> 16730170 | K8: 58 | L8: Delivered | M8: Approved
A9: PO00008 | B9: 45749 | C9: EMP0029 | D9: =IFERROR(INDEX(Dim_Employee!$B$2:$B$76,MATCH(C9,Dim_Employee!$A$2:$A$76,0)),"") -> Amaka Usman | E9: SPX Nigeria | F9: Fuel | G9: Natural Gas Supply Top-up | H9: 135 | I9: 365060.85 | J9: =H9*I9 -> 49283215 | K9: 42 | L9: Delivered | M9: Rejected
A10: PO00009 | B10: 45768 | C10: EMP0027 | D10: =IFERROR(INDEX(Dim_Employee!$B$2:$B$76,MATCH(C10,Dim_Employee!$A$2:$A$76,0)),"") -> Adaeze Onyeka | E10: SPX Nigeria | F10: Safety Equipment | G10: Gas Detectors | H10: 20 | I10: 298001.19 | J10: =H10*I10 -> 5960023.8 | K10: 6 | L10: Pending Dispatch | M10: Rejected
A11: PO00010 | B11: 45680 | C11: EMP0024 | D11: =IFERROR(INDEX(Dim_Employee!$B$2:$B$76,MATCH(C11,Dim_Employee!$A$2:$A$76,0)),"") -> Titilayo Okafor | E11: SPX Nigeria | F11: Spare Parts | G11: Turbine Blade Set | H11: 68 | I11: 229749.74 | J11: =H11*I11 -> 15622982 | K11: 28 | L11: Pending Dispatch | M11: Pending Approval
A12: PO00011 | B12: 45890 | C12: EMP0022 | D12: =IFERROR(INDEX(Dim_Employee!$B$2:$B$76,MATCH(C12,Dim_Employee!$A$2:$A$76,0)),"") -> Zainab Igwe | E12: Total Energies Nigeria | F12: Consumables | G12: Welding Consumables | H12: 177 | I12: 36634.48 | J12: =H12*I12 -> 6484303 | K12: 23 | L12: Delayed | M12: Rejected
A13: PO00012 | B13: 45872 | C13: EMP0026 | D13: =IFERROR(INDEX(Dim_Employee!$B$2:$B$76,MATCH(C13,Dim_Employee!$A$2:$A$76,0)),"") -> Ibrahim Abubakar | E13: OilServ Ltd | F13: Safety Equipment | G13: Fire Suppression Cylinder | H13: 109 | I13: 271548.08 | J13: =H13*I13 -> 29598741 | K13: 26 | L13: Delayed | M13: Pending Approval
... A151: PO00150 | B151: 45700 | C151: EMP0024 | D151: =IFERROR(INDEX(Dim_Employee!$B$2:$B$76,MATCH(C151,Dim_Employee!$A$2:$A$76,0)),"") -> Titilayo Okafor | E151: Cummins West Africa | F151: IT Hardware | G151: SCADA Workstation | H151: 81 | I151: 181708.24 | J151: =H151*I151 -> 14718367 | K151: 31 | L151: Delayed | M151: Rejected

Sheet Admin
A1: Request_ID | B1: Date | C1: Employee_ID | D1: Employee_Name | E1: Request_Type | F1: Asset_Tag | G1: Location | H1: Priority | I1: Status | J1: Cost_NGN | K1: Closure_Date
A2: ADM0001 | B2: 45944 | C2: EMP0033 | D2: =IFERROR(INDEX(Dim_Employee!$B$2:$B$76,MATCH(C2,Dim_Employee!$A$2:$A$76,0)),"") -> Ngozi Balogun | E2: Fleet/Vehicle | F2: AST-9320 | G2: Head Office - Abuja | H2: Medium | I2: Cancelled | J2: 965660.87
A3: ADM0002 | B3: 45980 | C3: EMP0033 | D3: =IFERROR(INDEX(Dim_Employee!$B$2:$B$76,MATCH(C3,Dim_Employee!$A$2:$A$76,0)),"") -> Ngozi Balogun | E3: Facility Maintenance | F3: AST-8316 | G3: Guest House - Kogi | H3: Medium | I3: In Progress | J3: 113351.29
A4: ADM0003 | B4: 45982 | C4: EMP0035 | D4: =IFERROR(INDEX(Dim_Employee!$B$2:$B$76,MATCH(C4,Dim_Employee!$A$2:$A$76,0)),"") -> Ifeoma Balogun | E4: Fleet/Vehicle | F4: AST-8421 | G4: Head Office - Abuja | H4: Low | I4: Completed | J4: 998883.44 | K4: 46002
A5: ADM0004 | B5: 45688 | C5: EMP0030 | D5: =IFERROR(INDEX(Dim_Employee!$B$2:$B$76,MATCH(C5,Dim_Employee!$A$2:$A$76,0)),"") -> Yusuf Abubakar | E5: Asset Request | F5: AST-1492 | G5: Lagos Liaison Office | H5: High | I5: Completed | J5: 531434.68 | K5: 45695
A6: ADM0005 | B6: 45923 | C6: EMP0031 | D6: =IFERROR(INDEX(Dim_Employee!$B$2:$B$76,MATCH(C6,Dim_Employee!$A$2:$A$76,0)),"") -> Emmanuel Aliyu | E6: Office Supplies | F6: AST-5819 | G6: Lagos Liaison Office | H6: Low | I6: In Progress | J6: 796627.19
A7: ADM0006 | B7: 45993 | C7: EMP0033 | D7: =IFERROR(INDEX(Dim_Employee!$B$2:$B$76,MATCH(C7,Dim_Employee!$A$2:$A$76,0)),"") -> Ngozi Balogun | E7: Fleet/Vehicle | F7: AST-2363 | G7: Guest House - Kogi | H7: High | I7: Pending | J7: 910798.11
A8: ADM0007 | B8: 45805 | C8: EMP0034 | D8: =IFERROR(INDEX(Dim_Employee!$B$2:$B$76,MATCH(C8,Dim_Employee!$A$2:$A$76,0)),"") -> Peace Balogun | E8: Utility Payment | F8: AST-2768 | G8: Lagos Liaison Office | H8: Low | I8: Completed | J8: 1016667.4 | K8: 45808
A9: ADM0008 | B9: 45692 | C9: EMP0033 | D9: =IFERROR(INDEX(Dim_Employee!$B$2:$B$76,MATCH(C9,Dim_Employee!$A$2:$A$76,0)),"") -> Ngozi Balogun | E9: Office Supplies | F9: AST-1008 | G9: Head Office - Abuja | H9: Medium | I9: Completed | J9: 1112815.4 | K9: 45720
A10: ADM0009 | B10: 45898 | C10: EMP0030 | D10: =IFERROR(INDEX(Dim_Employee!$B$2:$B$76,MATCH(C10,Dim_Employee!$A$2:$A$76,0)),"") -> Yusuf Abubakar | E10: Office Supplies | F10: AST-7511 | G10: Lagos Liaison Office | H10: Low | I10: Cancelled | J10: 681658.89
A11: ADM0010 | B11: 46003 | C11: EMP0031 | D11: =IFERROR(INDEX(Dim_Employee!$B$2:$B$76,MATCH(C11,Dim_Employee!$A$2:$A$76,0)),"") -> Emmanuel Aliyu | E11: Travel Request | F11: AST-2427 | G11: Guest House - Kogi | H11: High | I11: Pending | J11: 23103.67
A12: ADM0011 | B12: 45718 | C12: EMP0033 | D12: =IFERROR(INDEX(Dim_Employee!$B$2:$B$76,MATCH(C12,Dim_Employee!$A$2:$A$76,0)),"") -> Ngozi Balogun | E12: Asset Request | F12: AST-2655 | G12: Kogi Plant Site | H12: Low | I12: In Progress | J12: 560603.12
A13: ADM0012 | B13: 45748 | C13: EMP0033 | D13: =IFERROR(INDEX(Dim_Employee!$B$2:$B$76,MATCH(C13,Dim_Employee!$A$2:$A$76,0)),"") -> Ngozi Balogun | E13: Fleet/Vehicle | F13: AST-9337 | G13: Head Office - Abuja | H13: Medium | I13: In Progress | J13: 505980.44
A14: ADM0013 | B14: 45717 | C14: EMP0033 | D14: =IFERROR(INDEX(Dim_Employee!$B$2:$B$76,MATCH(C14,Dim_Employee!$A$2:$A$76,0)),"") -> Ngozi Balogun | E14: Fleet/Vehicle | F14: AST-4487 | G14: Kogi Plant Site | H14: High | I14: Cancelled | J14: 1037879.1
A15: ADM0014 | B15: 45813 | C15: EMP0034 | D15: =IFERROR(INDEX(Dim_Employee!$B$2:$B$76,MATCH(C15,Dim_Employee!$A$2:$A$76,0)),"") -> Peace Balogun | E15: Asset Request | F15: AST-7459 | G15: Kogi Plant Site | H15: Low | I15: Completed | J15: 1187215.5 | K15: 45820
A16: ADM0015 | B16: 45884 | C16: EMP0031 | D16: =IFERROR(INDEX(Dim_Employee!$B$2:$B$76,MATCH(C16,Dim_Employee!$A$2:$A$76,0)),"") -> Emmanuel Aliyu | E16: Facility Maintenance | F16: AST-6389 | G16: Guest House - Kogi | H16: Urgent | I16: Pending | J16: 92711.27
A17: ADM0016 | B17: 45764 | C17: EMP0030 | D17: =IFERROR(INDEX(Dim_Employee!$B$2:$B$76,MATCH(C17,Dim_Employee!$A$2:$A$76,0)),"") -> Yusuf Abubakar | E17: Facility Maintenance | F17: AST-7040 | G17: Guest House - Kogi | H17: Urgent | I17: In Progress | J17: 157029.21
A18: ADM0017 | B18: 45905 | C18: EMP0034 | D18: =IFERROR(INDEX(Dim_Employee!$B$2:$B$76,MATCH(C18,Dim_Employee!$A$2:$A$76,0)),"") -> Peace Balogun | E18: Fleet/Vehicle | F18: AST-3995 | G18: Head Office - Abuja | H18: High | I18: In Progress | J18: 1090566.4
A19: ADM0018 | B19: 45785 | C19: EMP0034 | D19: =IFERROR(INDEX(Dim_Employee!$B$2:$B$76,MATCH(C19,Dim_Employee!$A$2:$A$76,0)),"") -> Peace Balogun | E19: Asset Request | F19: AST-4220 | G19: Lagos Liaison Office | H19: Urgent | I19: In Progress | J19: 726223.39
A20: ADM0019 | B20: 45682 | C20: EMP0033 | D20: =IFERROR(INDEX(Dim_Employee!$B$2:$B$76,MATCH(C20,Dim_Employee!$A$2:$A$76,0)),"") -> Ngozi Balogun | E20: Facility Maintenance | F20: AST-9394 | G20: Guest House - Kogi | H20: Medium | I20: Completed | J20: 889095.25 | K20: 45686
A21: ADM0020 | B21: 45789 | C21: EMP0033 | D21: =IFERROR(INDEX(Dim_Employee!$B$2:$B$76,MATCH(C21,Dim_Employee!$A$2:$A$76,0)),"") -> Ngozi Balogun | E21: Utility Payment | F21: AST-9044 | G21: Guest House - Kogi | H21: Medium | I21: Cancelled | J21: 1115437.2
A22: ADM0021 | B22: 45722 | C22: EMP0030 | D22: =IFERROR(INDEX(Dim_Employee!$B$2:$B$76,MATCH(C22,Dim_Employee!$A$2:$A$76,0)),"") -> Yusuf Abubakar | E22: Fleet/Vehicle | F22: AST-2214 | G22: Guest House - Kogi | H22: Medium | I22: In Progress | J22: 1101245.4
A23: ADM0022 | B23: 45666 | C23: EMP0031 | D23: =IFERROR(INDEX(Dim_Employee!$B$2:$B$76,MATCH(C23,Dim_Employee!$A$2:$A$76,0)),"") -> Emmanuel Aliyu | E23: Fleet/Vehicle | F23: AST-8302 | G23: Head Office - Abuja | H23: Low | I23: Completed | J23: 60684.77 | K23: 45675
A24: ADM0023 | B24: 45846 | C24: EMP0032 | D24: =IFERROR(INDEX(Dim_Employee!$B$2:$B$76,MATCH(C24,Dim_Employee!$A$2:$A$76,0)),"") -> Blessing Nnamdi | E24: Facility Maintenance | F24: AST-6933 | G24: Head Office - Abuja | H24: Urgent | I24: In Progress | J24: 1176689.6
A25: ADM0024 | B25: 46011 | C25: EMP0035 | D25: =IFERROR(INDEX(Dim_Employee!$B$2:$B$76,MATCH(C25,Dim_Employee!$A$2:$A$76,0)),"") -> Ifeoma Balogun | E25: Utility Payment | F25: AST-1574 | G25: Kogi Plant Site | H25: Urgent | I25: In Progress | J25: 1092703.9
A26: ADM0025 | B26: 45817 | C26: EMP0035 | D26: =IFERROR(INDEX(Dim_Employee!$B$2:$B$76,MATCH(C26,Dim_Employee!$A$2:$A$76,0)),"") -> Ifeoma Balogun | E26: Utility Payment | F26: AST-2226 | G26: Lagos Liaison Office | H26: Low | I26: Completed | J26: 877945.09 | K26: 45818
A27: ADM0026 | B27: 45727 | C27: EMP0032 | D27: =IFERROR(INDEX(Dim_Employee!$B$2:$B$76,MATCH(C27,Dim_Employee!$A$2:$A$76,0)),"") -> Blessing Nnamdi | E27: Fleet/Vehicle | F27: AST-9947 | G27: Guest House - Kogi | H27: Low | I27: Completed | J27: 1080734.1 | K27: 45730
A28: ADM0027 | B28: 46018 | C28: EMP0035 | D28: =IFERROR(INDEX(Dim_Employee!$B$2:$B$76,MATCH(C28,Dim_Employee!$A$2:$A$76,0)),"") -> Ifeoma Balogun | E28: Travel Request | F28: AST-6764 | G28: Kogi Plant Site | H28: Urgent | I28: In Progress | J28: 1081498.9
A29: ADM0028 | B29: 45673 | C29: EMP0033 | D29: =IFERROR(INDEX(Dim_Employee!$B$2:$B$76,MATCH(C29,Dim_Employee!$A$2:$A$76,0)),"") -> Ngozi Balogun | E29: Utility Payment | F29: AST-1238 | G29: Lagos Liaison Office | H29: Urgent | I29: Cancelled | J29: 701301.28
A30: ADM0029 | B30: 45694 | C30: EMP0034 | D30: =IFERROR(INDEX(Dim_Employee!$B$2:$B$76,MATCH(C30,Dim_Employee!$A$2:$A$76,0)),"") -> Peace Balogun | E30: Office Supplies | F30: AST-2893 | G30: Guest House - Kogi | H30: Urgent | I30: Completed | J30: 875207.46 | K30: 45697
A31: ADM0030 | B31: 46013 | C31: EMP0033 | D31: =IFERROR(INDEX(Dim_Employee!$B$2:$B$76,MATCH(C31,Dim_Employee!$A$2:$A$76,0)),"") -> Ngozi Balogun | E31: Fleet/Vehicle | F31: AST-8579 | G31: Kogi Plant Site | H31: Low | I31: Cancelled | J31: 375730.81
A32: ADM0031 | B32: 45904 | C32: EMP0030 | D32: =IFERROR(INDEX(Dim_Employee!$B$2:$B$76,MATCH(C32,Dim_Employee!$A$2:$A$76,0)),"") -> Yusuf Abubakar | E32: Office Supplies | F32: AST-2849 | G32: Lagos Liaison Office | H32: Urgent | I32: Completed | J32: 310717.11 | K32: 45912
A33: ADM0032 | B33: 45846 | C33: EMP0030 | D33: =IFERROR(INDEX(Dim_Employee!$B$2:$B$76,MATCH(C33,Dim_Employee!$A$2:$A$76,0)),"") -> Yusuf Abubakar | E33: Asset Request | F33: AST-4318 | G33: Head Office - Abuja | H33: High | I33: Pending | J33: 793688.06
A34: ADM0033 | B34: 45913 | C34: EMP0033 | D34: =IFERROR(INDEX(Dim_Employee!$B$2:$B$76,MATCH(C34,Dim_Employee!$A$2:$A$76,0)),"") -> Ngozi Balogun | E34: Travel Request | F34: AST-7631 | G34: Guest House - Kogi | H34: Medium | I34: In Progress | J34: 762836.89
A35: ADM0034 | B35: 45767 | C35: EMP0031 | D35: =IFERROR(INDEX(Dim_Employee!$B$2:$B$76,MATCH(C35,Dim_Employee!$A$2:$A$76,0)),"") -> Emmanuel Aliyu | E35: Asset Request | F35: AST-6185 | G35: Head Office - Abuja | H35: Medium | I35: Cancelled | J35: 165790.52
A36: ADM0035 | B36: 45678 | C36: EMP0032 | D36: =IFERROR(INDEX(Dim_Employee!$B$2:$B$76,MATCH(C36,Dim_Employee!$A$2:$A$76,0)),"") -> Blessing Nnamdi | E36: Asset Request | F36: AST-2848 | G36: Lagos Liaison Office | H36: Urgent | I36: Completed | J36: 333819.57 | K36: 45687
A37: ADM0036 | B37: 45869 | C37: EMP0031 | D37: =IFERROR(INDEX(Dim_Employee!$B$2:$B$76,MATCH(C37,Dim_Employee!$A$2:$A$76,0)),"") -> Emmanuel Aliyu | E37: Office Supplies | F37: AST-9519 | G37: Lagos Liaison Office | H37: High | I37: Cancelled | J37: 860950.52
A38: ADM0037 | B38: 45889 | C38: EMP0034 | D38: =IFERROR(INDEX(Dim_Employee!$B$2:$B$76,MATCH(C38,Dim_Employee!$A$2:$A$76,0)),"") -> Peace Balogun | E38: Facility Maintenance | F38: AST-1515 | G38: Guest House - Kogi | H38: Low | I38: Pending | J38: 815514.38
A39: ADM0038 | B39: 45950 | C39: EMP0032 | D39: =IFERROR(INDEX(Dim_Employee!$B$2:$B$76,MATCH(C39,Dim_Employee!$A$2:$A$76,0)),"") -> Blessing Nnamdi | E39: Travel Request | F39: AST-1313 | G39: Head Office - Abuja | H39: Urgent | I39: Pending | J39: 548524.73
A40: ADM0039 | B40: 45794 | C40: EMP0030 | D40: =IFERROR(INDEX(Dim_Employee!$B$2:$B$76,MATCH(C40,Dim_Employee!$A$2:$A$76,0)),"") -> Yusuf Abubakar | E40: Asset Request | F40: AST-1769 | G40: Kogi Plant Site | H40: Urgent | I40: In Progress | J40: 135279.14
...

Sheet Customer_Service
A1: Ticket_ID | B1: Date | C1: Employee_ID | D1: Employee_Name | E1: Customer_Name | F1: Customer_Type | G1: Issue_Category | H1: Priority | I1: Status | J1: Resolution_Time_Hours | K1: Satisfaction_Score
A2: CS00001 | B2: 45749 | C2: EMP0038 | D2: =IFERROR(INDEX(Dim_Employee!$B$2:$B$76,MATCH(C2,Dim_Employee!$A$2:$A$76,0)),"") -> Ibrahim Nwosu | E2: Ikeja Electric Disco | F2: Bulk Trader | G2: Billing Dispute | H2: Urgent | I2: In Progress
A3: CS00002 | B3: 45752 | C3: EMP0042 | D3: =IFERROR(INDEX(Dim_Employee!$B$2:$B$76,MATCH(C3,Dim_Employee!$A$2:$A$76,0)),"") -> Funmilayo Yakubu | E3: Kaduna Disco | F3: Distribution Company | G3: Service Request | H3: Medium | I3: Resolved | J3: 30.7 | K3: 2
A4: CS00003 | B4: 45962 | C4: EMP0040 | D4: =IFERROR(INDEX(Dim_Employee!$B$2:$B$76,MATCH(C4,Dim_Employee!$A$2:$A$76,0)),"") -> Emeka Bello | E4: Nigerian Bulk Electricity Trading Plc | F4: Distribution Company | G4: Contract Query | H4: Medium | I4: Pending Customer Response
A5: CS00004 | B5: 45746 | C5: EMP0038 | D5: =IFERROR(INDEX(Dim_Employee!$B$2:$B$76,MATCH(C5,Dim_Employee!$A$2:$A$76,0)),"") -> Ibrahim Nwosu | E5: Kano Disco | F5: Government Agency | G5: Service Request | H5: Urgent | I5: Pending Customer Response
A6: CS00005 | B6: 45906 | C6: EMP0042 | D6: =IFERROR(INDEX(Dim_Employee!$B$2:$B$76,MATCH(C6,Dim_Employee!$A$2:$A$76,0)),"") -> Funmilayo Yakubu | E6: Port Harcourt Disco | F6: Bulk Trader | G6: Service Request | H6: Low | I6: Escalated
A7: CS00006 | B7: 45862 | C7: EMP0039 | D7: =IFERROR(INDEX(Dim_Employee!$B$2:$B$76,MATCH(C7,Dim_Employee!$A$2:$A$76,0)),"") -> Segun Ogunleye | E7: Ikeja Electric Disco | F7: Distribution Company | G7: Power Supply Interruption | H7: Urgent | I7: In Progress
A8: CS00007 | B8: 45687 | C8: EMP0040 | D8: =IFERROR(INDEX(Dim_Employee!$B$2:$B$76,MATCH(C8,Dim_Employee!$A$2:$A$76,0)),"") -> Emeka Bello | E8: Ibadan Disco | F8: Distribution Company | G8: Contract Query | H8: High | I8: Escalated
A9: CS00008 | B9: 45873 | C9: EMP0039 | D9: =IFERROR(INDEX(Dim_Employee!$B$2:$B$76,MATCH(C9,Dim_Employee!$A$2:$A$76,0)),"") -> Segun Ogunleye | E9: Eko Disco | F9: Bulk Trader | G9: Power Supply Interruption | H9: High | I9: In Progress
A10: CS00009 | B10: 45922 | C10: EMP0037 | D10: =IFERROR(INDEX(Dim_Employee!$B$2:$B$76,MATCH(C10,Dim_Employee!$A$2:$A$76,0)),"") -> Yusuf Usman | E10: Eko Disco | F10: Government Agency | G10: Service Request | H10: High | I10: Escalated
A11: CS00010 | B11: 45658 | C11: EMP0040 | D11: =IFERROR(INDEX(Dim_Employee!$B$2:$B$76,MATCH(C11,Dim_Employee!$A$2:$A$76,0)),"") -> Emeka Bello | E11: Ibadan Disco | F11: Distribution Company | G11: Power Supply Interruption | H11: Low | I11: Resolved | J11: 15.3 | K11: 2
A12: CS00011 | B12: 45972 | C12: EMP0038 | D12: =IFERROR(INDEX(Dim_Employee!$B$2:$B$76,MATCH(C12,Dim_Employee!$A$2:$A$76,0)),"") -> Ibrahim Nwosu | E12: Nigerian Bulk Electricity Trading Plc | F12: Distribution Company | G12: Contract Query | H12: Urgent | I12: Escalated
A13: CS00012 | B13: 45667 | C13: EMP0036 | D13: =IFERROR(INDEX(Dim_Employee!$B$2:$B$76,MATCH(C13,Dim_Employee!$A$2:$A$76,0)),"") -> Damilola Balogun | E13: Ibadan Disco | F13: Bulk Trader | G13: Power Supply Interruption | H13: Low | I13: Escalated
A14: CS00013 | B14: 45764 | C14: EMP0042 | D14: =IFERROR(INDEX(Dim_Employee!$B$2:$B$76,MATCH(C14,Dim_Employee!$A$2:$A$76,0)),"") -> Funmilayo Yakubu | E14: Ikeja Electric Disco | F14: Government Agency | G14: Contract Query | H14: Urgent | I14: Pending Customer Response
A15: CS00014 | B15: 45819 | C15: EMP0037 | D15: =IFERROR(INDEX(Dim_Employee!$B$2:$B$76,MATCH(C15,Dim_Employee!$A$2:$A$76,0)),"") -> Yusuf Usman | E15: Kano Disco | F15: Bulk Trader | G15: Billing Dispute | H15: High | I15: Escalated
A16: CS00015 | B16: 45712 | C16: EMP0039 | D16: =IFERROR(INDEX(Dim_Employee!$B$2:$B$76,MATCH(C16,Dim_Employee!$A$2:$A$76,0)),"") -> Segun Ogunleye | E16: Port Harcourt Disco | F16: Government Agency | G16: Contract Query | H16: Low | I16: Resolved | J16: 35.2 | K16: 2
A17: CS00016 | B17: 45664 | C17: EMP0041 | D17: =IFERROR(INDEX(Dim_Employee!$B$2:$B$76,MATCH(C17,Dim_Employee!$A$2:$A$76,0)),"") -> Chukwudi Okonkwo | E17: Port Harcourt Disco | F17: Government Agency | G17: Contract Query | H17: Medium | I17: Pending Customer Response
A18: CS00017 | B18: 45763 | C18: EMP0038 | D18: =IFERROR(INDEX(Dim_Employee!$B$2:$B$76,MATCH(C18,Dim_Employee!$A$2:$A$76,0)),"") -> Ibrahim Nwosu | E18: Eko Disco | F18: Bulk Trader | G18: Contract Query | H18: High | I18: Resolved | J18: 44.5 | K18: 1
A19: CS00018 | B19: 45942 | C19: EMP0038 | D19: =IFERROR(INDEX(Dim_Employee!$B$2:$B$76,MATCH(C19,Dim_Employee!$A$2:$A$76,0)),"") -> Ibrahim Nwosu | E19: Abuja Disco | F19: Bulk Trader | G19: Power Supply Interruption | H19: Medium | I19: Pending Customer Response
A20: CS00019 | B20: 45946 | C20: EMP0039 | D20: =IFERROR(INDEX(Dim_Employee!$B$2:$B$76,MATCH(C20,Dim_Employee!$A$2:$A$76,0)),"") -> Segun Ogunleye | E20: Enugu Disco | F20: Government Agency | G20: Metering/Data Issue | H20: Urgent | I20: Resolved | J20: 32.3 | K20: 3
A21: CS00020 | B21: 45705 | C21: EMP0042 | D21: =IFERROR(INDEX(Dim_Employee!$B$2:$B$76,MATCH(C21,Dim_Employee!$A$2:$A$76,0)),"") -> Funmilayo Yakubu | E21: Abuja Disco | F21: Distribution Company | G21: Service Request | H21: Low | I21: Pending Customer Response
A22: CS00021 | B22: 45750 | C22: EMP0037 | D22: =IFERROR(INDEX(Dim_Employee!$B$2:$B$76,MATCH(C22,Dim_Employee!$A$2:$A$76,0)),"") -> Yusuf Usman | E22: Ibadan Disco | F22: Bulk Trader | G22: Billing Dispute | H22: Urgent | I22: In Progress
A23: CS00022 | B23: 45738 | C23: EMP0040 | D23: =IFERROR(INDEX(Dim_Employee!$B$2:$B$76,MATCH(C23,Dim_Employee!$A$2:$A$76,0)),"") -> Emeka Bello | E23: Abuja Disco | F23: Bulk Trader | G23: Contract Query | H23: Low | I23: Resolved | J23: 10.5 | K23: 1
A24: CS00023 | B24: 45919 | C24: EMP0038 | D24: =IFERROR(INDEX(Dim_Employee!$B$2:$B$76,MATCH(C24,Dim_Employee!$A$2:$A$76,0)),"") -> Ibrahim Nwosu | E24: Eko Disco | F24: Government Agency | G24: Power Supply Interruption | H24: Medium | I24: Pending Customer Response
A25: CS00024 | B25: 45905 | C25: EMP0042 | D25: =IFERROR(INDEX(Dim_Employee!$B$2:$B$76,MATCH(C25,Dim_Employee!$A$2:$A$76,0)),"") -> Funmilayo Yakubu | E25: Kaduna Disco | F25: Bulk Trader | G25: Service Request | H25: Low | I25: Pending Customer Response
A26: CS00025 | B26: 45971 | C26: EMP0041 | D26: =IFERROR(INDEX(Dim_Employee!$B$2:$B$76,MATCH(C26,Dim_Employee!$A$2:$A$76,0)),"") -> Chukwudi Okonkwo | E26: Kaduna Disco | F26: Distribution Company | G26: Service Request | H26: Low | I26: Pending Customer Response
A27: CS00026 | B27: 45754 | C27: EMP0038 | D27: =IFERROR(INDEX(Dim_Employee!$B$2:$B$76,MATCH(C27,Dim_Employee!$A$2:$A$76,0)),"") -> Ibrahim Nwosu | E27: Kaduna Disco | F27: Bulk Trader | G27: Contract Query | H27: Low | I27: Escalated
A28: CS00027 | B28: 45762 | C28: EMP0040 | D28: =IFERROR(INDEX(Dim_Employee!$B$2:$B$76,MATCH(C28,Dim_Employee!$A$2:$A$76,0)),"") -> Emeka Bello | E28: Nigerian Bulk Electricity Trading Plc | F28: Bulk Trader | G28: Metering/Data Issue | H28: Low | I28: Pending Customer Response
A29: CS00028 | B29: 45787 | C29: EMP0040 | D29: =IFERROR(INDEX(Dim_Employee!$B$2:$B$76,MATCH(C29,Dim_Employee!$A$2:$A$76,0)),"") -> Emeka Bello | E29: Nigerian Bulk Electricity Trading Plc | F29: Bulk Trader | G29: Service Request | H29: Medium | I29: In Progress
A30: CS00029 | B30: 45951 | C30: EMP0038 | D30: =IFERROR(INDEX(Dim_Employee!$B$2:$B$76,MATCH(C30,Dim_Employee!$A$2:$A$76,0)),"") -> Ibrahim Nwosu | E30: Ibadan Disco | F30: Government Agency | G30: Power Supply Interruption | H30: Low | I30: In Progress
A31: CS00030 | B31: 45700 | C31: EMP0041 | D31: =IFERROR(INDEX(Dim_Employee!$B$2:$B$76,MATCH(C31,Dim_Employee!$A$2:$A$76,0)),"") -> Chukwudi Okonkwo | E31: Eko Disco | F31: Distribution Company | G31: Contract Query | H31: Urgent | I31: In Progress
A32: CS00031 | B32: 45826 | C32: EMP0041 | D32: =IFERROR(INDEX(Dim_Employee!$B$2:$B$76,MATCH(C32,Dim_Employee!$A$2:$A$76,0)),"") -> Chukwudi Okonkwo | E32: Abuja Disco | F32: Bulk Trader | G32: Metering/Data Issue | H32: Urgent | I32: Escalated
A33: CS00032 | B33: 45727 | C33: EMP0036 | D33: =IFERROR(INDEX(Dim_Employee!$B$2:$B$76,MATCH(C33,Dim_Employee!$A$2:$A$76,0)),"") -> Damilola Balogun | E33: Ibadan Disco | F33: Government Agency | G33: Service Request | H33: Low | I33: Pending Customer Response
A34: CS00033 | B34: 45744 | C34: EMP0040 | D34: =IFERROR(INDEX(Dim_Employee!$B$2:$B$76,MATCH(C34,Dim_Employee!$A$2:$A$76,0)),"") -> Emeka Bello | E34: Kaduna Disco | F34: Government Agency | G34: Power Supply Interruption | H34: Low | I34: Escalated
A35: CS00034 | B35: 45781 | C35: EMP0042 | D35: =IFERROR(INDEX(Dim_Employee!$B$2:$B$76,MATCH(C35,Dim_Employee!$A$2:$A$76,0)),"") -> Funmilayo Yakubu | E35: Kaduna Disco | F35: Distribution Company | G35: Power Supply Interruption | H35: Low | I35: Resolved | J35: 28.4 | K35: 3
A36: CS00035 | B36: 45815 | C36: EMP0039 | D36: =IFERROR(INDEX(Dim_Employee!$B$2:$B$76,MATCH(C36,Dim_Employee!$A$2:$A$76,0)),"") -> Segun Ogunleye | E36: Port Harcourt Disco | F36: Government Agency | G36: Service Request | H36: Low | I36: Resolved | J36: 39.3 | K36: 2
A37: CS00036 | B37: 45868 | C37: EMP0037 | D37: =IFERROR(INDEX(Dim_Employee!$B$2:$B$76,MATCH(C37,Dim_Employee!$A$2:$A$76,0)),"") -> Yusuf Usman | E37: Enugu Disco | F37: Distribution Company | G37: Power Supply Interruption | H37: Urgent | I37: In Progress
A38: CS00037 | B38: 45746 | C38: EMP0036 | D38: =IFERROR(INDEX(Dim_Employee!$B$2:$B$76,MATCH(C38,Dim_Employee!$A$2:$A$76,0)),"") -> Damilola Balogun | E38: Kaduna Disco | F38: Government Agency | G38: Power Supply Interruption | H38: High | I38: Pending Customer Response
A39: CS00038 | B39: 45685 | C39: EMP0037 | D39: =IFERROR(INDEX(Dim_Employee!$B$2:$B$76,MATCH(C39,Dim_Employee!$A$2:$A$76,0)),"") -> Yusuf Usman | E39: Ikeja Electric Disco | F39: Government Agency | G39: Power Supply Interruption | H39: Urgent | I39: Escalated
A40: CS00039 | B40: 45977 | C40: EMP0039 | D40: =IFERROR(INDEX(Dim_Employee!$B$2:$B$76,MATCH(C40,Dim_Employee!$A$2:$A$76,0)),"") -> Segun Ogunleye | E40: Port Harcourt Disco | F40: Bulk Trader | G40: Contract Query | H40: Urgent | I40: Resolved | J40: 45.6 | K40: 4
...

Sheet IT
A1: Ticket_ID | B1: Date | C1: Employee_ID | D1: Employee_Name | E1: System_Affected | F1: Issue_Type | G1: Priority | H1: Status | I1: Resolution_Time_Hours | J1: Downtime_Minutes
A2: ITK00001 | B2: 45761 | C2: EMP0046 | D2: =IFERROR(INDEX(Dim_Employee!$B$2:$B$76,MATCH(C2,Dim_Employee!$A$2:$A$76,0)),"") -> Musa Yakubu | E2: Email/Collaboration | F2: Hardware Failure | G2: Low | H2: In Progress | J2: 0
A3: ITK00002 | B3: 45860 | C3: EMP0046 | D3: =IFERROR(INDEX(Dim_Employee!$B$2:$B$76,MATCH(C3,Dim_Employee!$A$2:$A$76,0)),"") -> Musa Yakubu | E3: Access Control System | F3: System Outage | G3: Medium | H3: Open | J3: 0
A4: ITK00003 | B4: 45785 | C4: EMP0047 | D4: =IFERROR(INDEX(Dim_Employee!$B$2:$B$76,MATCH(C4,Dim_Employee!$A$2:$A$76,0)),"") -> Fatima Abubakar | E4: Email/Collaboration | F4: Software Bug | G4: Low | H4: Open | J4: 225
A5: ITK00004 | B5: 46003 | C5: EMP0044 | D5: =IFERROR(INDEX(Dim_Employee!$B$2:$B$76,MATCH(C5,Dim_Employee!$A$2:$A$76,0)),"") -> Adaeze Adeyemi | E5: SCADA | F5: Access Request | G5: High | H5: Closed | I5: 45.4 | J5: 0
A6: ITK00005 | B6: 45765 | C6: EMP0043 | D6: =IFERROR(INDEX(Dim_Employee!$B$2:$B$76,MATCH(C6,Dim_Employee!$A$2:$A$76,0)),"") -> Suleiman Garba | E6: SCADA | F6: Access Request | G6: Low | H6: Open | J6: 112
A7: ITK00006 | B7: 45911 | C7: EMP0049 | D7: =IFERROR(INDEX(Dim_Employee!$B$2:$B$76,MATCH(C7,Dim_Employee!$A$2:$A$76,0)),"") -> Rukayat Ude | E7: Email/Collaboration | F7: Access Request | G7: Low | H7: Open | J7: 0
A8: ITK00007 | B8: 45867 | C8: EMP0046 | D8: =IFERROR(INDEX(Dim_Employee!$B$2:$B$76,MATCH(C8,Dim_Employee!$A$2:$A$76,0)),"") -> Musa Yakubu | E8: Corporate Network | F8: Software Bug | G8: Low | H8: On Hold | J8: 0
A9: ITK00008 | B9: 45847 | C9: EMP0043 | D9: =IFERROR(INDEX(Dim_Employee!$B$2:$B$76,MATCH(C9,Dim_Employee!$A$2:$A$76,0)),"") -> Suleiman Garba | E9: Access Control System | F9: Security Alert | G9: High | H9: In Progress | J9: 93
A10: ITK00009 | B10: 45888 | C10: EMP0049 | D10: =IFERROR(INDEX(Dim_Employee!$B$2:$B$76,MATCH(C10,Dim_Employee!$A$2:$A$76,0)),"") -> Rukayat Ude | E10: Corporate Network | F10: Access Request | G10: High | H10: Open | J10: 0
A11: ITK00010 | B11: 45793 | C11: EMP0043 | D11: =IFERROR(INDEX(Dim_Employee!$B$2:$B$76,MATCH(C11,Dim_Employee!$A$2:$A$76,0)),"") -> Suleiman Garba | E11: Corporate Network | F11: Performance Issue | G11: Medium | H11: Open | J11: 0
A12: ITK00011 | B12: 46006 | C12: EMP0044 | D12: =IFERROR(INDEX(Dim_Employee!$B$2:$B$76,MATCH(C12,Dim_Employee!$A$2:$A$76,0)),"") -> Adaeze Adeyemi | E12: ERP System | F12: Performance Issue | G12: High | H12: Closed | I12: 35.8 | J12: 0
A13: ITK00012 | B13: 45878 | C13: EMP0043 | D13: =IFERROR(INDEX(Dim_Employee!$B$2:$B$76,MATCH(C13,Dim_Employee!$A$2:$A$76,0)),"") -> Suleiman Garba | E13: SCADA | F13: System Outage | G13: Critical | H13: In Progress | J13: 84
A14: ITK00013 | B14: 45762 | C14: EMP0047 | D14: =IFERROR(INDEX(Dim_Employee!$B$2:$B$76,MATCH(C14,Dim_Employee!$A$2:$A$76,0)),"") -> Fatima Abubakar | E14: SCADA | F14: Performance Issue | G14: High | H14: Closed | I14: 19.7 | J14: 129
A15: ITK00014 | B15: 45770 | C15: EMP0043 | D15: =IFERROR(INDEX(Dim_Employee!$B$2:$B$76,MATCH(C15,Dim_Employee!$A$2:$A$76,0)),"") -> Suleiman Garba | E15: Email/Collaboration | F15: Hardware Failure | G15: Medium | H15: Closed | I15: 28 | J15: 114
A16: ITK00015 | B16: 45822 | C16: EMP0049 | D16: =IFERROR(INDEX(Dim_Employee!$B$2:$B$76,MATCH(C16,Dim_Employee!$A$2:$A$76,0)),"") -> Rukayat Ude | E16: ERP System | F16: Access Request | G16: Low | H16: Open | J16: 94
A17: ITK00016 | B17: 45686 | C17: EMP0044 | D17: =IFERROR(INDEX(Dim_Employee!$B$2:$B$76,MATCH(C17,Dim_Employee!$A$2:$A$76,0)),"") -> Adaeze Adeyemi | E17: ERP System | F17: Software Bug | G17: High | H17: On Hold | J17: 0
A18: ITK00017 | B18: 45948 | C18: EMP0046 | D18: =IFERROR(INDEX(Dim_Employee!$B$2:$B$76,MATCH(C18,Dim_Employee!$A$2:$A$76,0)),"") -> Musa Yakubu | E18: SCADA | F18: System Outage | G18: Critical | H18: On Hold | J18: 0
A19: ITK00018 | B19: 45854 | C19: EMP0046 | D19: =IFERROR(INDEX(Dim_Employee!$B$2:$B$76,MATCH(C19,Dim_Employee!$A$2:$A$76,0)),"") -> Musa Yakubu | E19: Access Control System | F19: Performance Issue | G19: Critical | H19: On Hold | J19: 0
A20: ITK00019 | B20: 45886 | C20: EMP0047 | D20: =IFERROR(INDEX(Dim_Employee!$B$2:$B$76,MATCH(C20,Dim_Employee!$A$2:$A$76,0)),"") -> Fatima Abubakar | E20: Corporate Network | F20: Software Bug | G20: Low | H20: Closed | I20: 25 | J20: 151
A21: ITK00020 | B21: 45789 | C21: EMP0047 | D21: =IFERROR(INDEX(Dim_Employee!$B$2:$B$76,MATCH(C21,Dim_Employee!$A$2:$A$76,0)),"") -> Fatima Abubakar | E21: CCTV/Security System | F21: Software Bug | G21: High | H21: Closed | I21: 44.8 | J21: 112
A22: ITK00021 | B22: 45863 | C22: EMP0044 | D22: =IFERROR(INDEX(Dim_Employee!$B$2:$B$76,MATCH(C22,Dim_Employee!$A$2:$A$76,0)),"") -> Adaeze Adeyemi | E22: SCADA | F22: Performance Issue | G22: Critical | H22: On Hold | J22: 0
A23: ITK00022 | B23: 45730 | C23: EMP0043 | D23: =IFERROR(INDEX(Dim_Employee!$B$2:$B$76,MATCH(C23,Dim_Employee!$A$2:$A$76,0)),"") -> Suleiman Garba | E23: SCADA | F23: System Outage | G23: High | H23: In Progress | J23: 222
A24: ITK00023 | B24: 45923 | C24: EMP0045 | D24: =IFERROR(INDEX(Dim_Employee!$B$2:$B$76,MATCH(C24,Dim_Employee!$A$2:$A$76,0)),"") -> Chiamaka Bakare | E24: Corporate Network | F24: Hardware Failure | G24: Medium | H24: Closed | I24: 9.3 | J24: 82
A25: ITK00024 | B25: 45987 | C25: EMP0047 | D25: =IFERROR(INDEX(Dim_Employee!$B$2:$B$76,MATCH(C25,Dim_Employee!$A$2:$A$76,0)),"") -> Fatima Abubakar | E25: ERP System | F25: System Outage | G25: Low | H25: Closed | I25: 41.6 | J25: 67
A26: ITK00025 | B26: 45909 | C26: EMP0047 | D26: =IFERROR(INDEX(Dim_Employee!$B$2:$B$76,MATCH(C26,Dim_Employee!$A$2:$A$76,0)),"") -> Fatima Abubakar | E26: ERP System | F26: System Outage | G26: Critical | H26: On Hold | J26: 0
A27: ITK00026 | B27: 45691 | C27: EMP0049 | D27: =IFERROR(INDEX(Dim_Employee!$B$2:$B$76,MATCH(C27,Dim_Employee!$A$2:$A$76,0)),"") -> Rukayat Ude | E27: ERP System | F27: Access Request | G27: Medium | H27: Closed | I27: 37.1 | J27: 0
A28: ITK00027 | B28: 45770 | C28: EMP0043 | D28: =IFERROR(INDEX(Dim_Employee!$B$2:$B$76,MATCH(C28,Dim_Employee!$A$2:$A$76,0)),"") -> Suleiman Garba | E28: Corporate Network | F28: System Outage | G28: Critical | H28: Open | J28: 83
A29: ITK00028 | B29: 45896 | C29: EMP0044 | D29: =IFERROR(INDEX(Dim_Employee!$B$2:$B$76,MATCH(C29,Dim_Employee!$A$2:$A$76,0)),"") -> Adaeze Adeyemi | E29: Email/Collaboration | F29: System Outage | G29: Low | H29: On Hold | J29: 164
A30: ITK00029 | B30: 45819 | C30: EMP0048 | D30: =IFERROR(INDEX(Dim_Employee!$B$2:$B$76,MATCH(C30,Dim_Employee!$A$2:$A$76,0)),"") -> Rukayat Usman | E30: CCTV/Security System | F30: Performance Issue | G30: Critical | H30: In Progress | J30: 0
A31: ITK00030 | B31: 45980 | C31: EMP0046 | D31: =IFERROR(INDEX(Dim_Employee!$B$2:$B$76,MATCH(C31,Dim_Employee!$A$2:$A$76,0)),"") -> Musa Yakubu | E31: Corporate Network | F31: Security Alert | G31: Medium | H31: Closed | I31: 39.3 | J31: 0
A32: ITK00031 | B32: 46013 | C32: EMP0048 | D32: =IFERROR(INDEX(Dim_Employee!$B$2:$B$76,MATCH(C32,Dim_Employee!$A$2:$A$76,0)),"") -> Rukayat Usman | E32: Access Control System | F32: Hardware Failure | G32: Low | H32: In Progress | J32: 31
A33: ITK00032 | B33: 45970 | C33: EMP0044 | D33: =IFERROR(INDEX(Dim_Employee!$B$2:$B$76,MATCH(C33,Dim_Employee!$A$2:$A$76,0)),"") -> Adaeze Adeyemi | E33: Access Control System | F33: Access Request | G33: High | H33: Open | J33: 226
A34: ITK00033 | B34: 45842 | C34: EMP0044 | D34: =IFERROR(INDEX(Dim_Employee!$B$2:$B$76,MATCH(C34,Dim_Employee!$A$2:$A$76,0)),"") -> Adaeze Adeyemi | E34: Corporate Network | F34: Hardware Failure | G34: Medium | H34: Closed | I34: 47.8 | J34: 0
A35: ITK00034 | B35: 45971 | C35: EMP0044 | D35: =IFERROR(INDEX(Dim_Employee!$B$2:$B$76,MATCH(C35,Dim_Employee!$A$2:$A$76,0)),"") -> Adaeze Adeyemi | E35: Email/Collaboration | F35: Access Request | G35: Critical | H35: Closed | I35: 30.5 | J35: 0
A36: ITK00035 | B36: 45778 | C36: EMP0044 | D36: =IFERROR(INDEX(Dim_Employee!$B$2:$B$76,MATCH(C36,Dim_Employee!$A$2:$A$76,0)),"") -> Adaeze Adeyemi | E36: Email/Collaboration | F36: Software Bug | G36: Low | H36: Closed | I36: 45.2 | J36: 169
A37: ITK00036 | B37: 46004 | C37: EMP0045 | D37: =IFERROR(INDEX(Dim_Employee!$B$2:$B$76,MATCH(C37,Dim_Employee!$A$2:$A$76,0)),"") -> Chiamaka Bakare | E37: CCTV/Security System | F37: Hardware Failure | G37: Medium | H37: Closed | I37: 42 | J37: 205
A38: ITK00037 | B38: 45770 | C38: EMP0046 | D38: =IFERROR(INDEX(Dim_Employee!$B$2:$B$76,MATCH(C38,Dim_Employee!$A$2:$A$76,0)),"") -> Musa Yakubu | E38: Email/Collaboration | F38: Security Alert | G38: Low | H38: On Hold | J38: 99
A39: ITK00038 | B39: 45995 | C39: EMP0045 | D39: =IFERROR(INDEX(Dim_Employee!$B$2:$B$76,MATCH(C39,Dim_Employee!$A$2:$A$76,0)),"") -> Chiamaka Bakare | E39: Corporate Network | F39: Access Request | G39: Low | H39: On Hold | J39: 140
A40: ITK00039 | B40: 45961 | C40: EMP0048 | D40: =IFERROR(INDEX(Dim_Employee!$B$2:$B$76,MATCH(C40,Dim_Employee!$A$2:$A$76,0)),"") -> Rukayat Usman | E40: Corporate Network | F40: Hardware Failure | G40: Critical | H40: In Progress | J40: 90
...

Sheet Accounts_Finance
A1: Transaction_ID | B1: Date | C1: Employee_ID | D1: Employee_Name | E1: Department_Linked | F1: Transaction_Type | G1: Category | H1: Amount_NGN | I1: Budget_NGN | J1: Variance_NGN | K1: Approval_Status
A2: FIN00001 | B2: 45670 | C2: EMP0056 | D2: =IFERROR(INDEX(Dim_Employee!$B$2:$B$76,MATCH(C2,Dim_Employee!$A$2:$A$76,0)),"") -> Tunde Ndukwe | E2: Supply Chain | F2: Opex | G2: Payroll Recharge | H2: 27130330 | I2: 36925660 | J2: =H2-I2 -> -9795330 | K2: Approved
A3: FIN00002 | B3: 45974 | C3: EMP0052 | D3: =IFERROR(INDEX(Dim_Employee!$B$2:$B$76,MATCH(C3,Dim_Employee!$A$2:$A$76,0)),"") -> Amaka Aliyu | E3: Human Resources | F3: Opex | G3: Payroll Recharge | H3: 51628609 | I3: 58328731 | J3: =H3-I3 -> -6700122.9 | K3: Rejected
A4: FIN00003 | B4: 45840 | C4: EMP0057 | D4: =IFERROR(INDEX(Dim_Employee!$B$2:$B$76,MATCH(C4,Dim_Employee!$A$2:$A$76,0)),"") -> Abdullahi Ojo | E4: Supply Chain | F4: Opex | G4: Utilities | H4: 32897432 | I4: 37622597 | J4: =H4-I4 -> -4725164.6 | K4: Rejected
A5: FIN00004 | B5: 45828 | C5: EMP0056 | D5: =IFERROR(INDEX(Dim_Employee!$B$2:$B$76,MATCH(C5,Dim_Employee!$A$2:$A$76,0)),"") -> Tunde Ndukwe | E5: IT | F5: Opex | G5: Maintenance Cost | H5: 31109358 | I5: 32637196 | J5: =H5-I5 -> -1527838.1 | K5: Rejected
A6: FIN00005 | B6: 45805 | C6: EMP0052 | D6: =IFERROR(INDEX(Dim_Employee!$B$2:$B$76,MATCH(C6,Dim_Employee!$A$2:$A$76,0)),"") -> Amaka Aliyu | E6: Customer Service | F6: Opex | G6: Maintenance Cost | H6: 38209312 | I6: 30776690 | J6: =H6-I6 -> 7432622.5 | K6: Rejected
A7: FIN00006 | B7: 46017 | C7: EMP0055 | D7: =IFERROR(INDEX(Dim_Employee!$B$2:$B$76,MATCH(C7,Dim_Employee!$A$2:$A$76,0)),"") -> Emeka Adeyemi | E7: Admin | F7: Revenue | G7: Ancillary Services | H7: 30905462 | I7: 33519411 | J7: =H7-I7 -> -2613949.8 | K7: Rejected
A8: FIN00007 | B8: 45944 | C8: EMP0051 | D8: =IFERROR(INDEX(Dim_Employee!$B$2:$B$76,MATCH(C8,Dim_Employee!$A$2:$A$76,0)),"") -> Ngozi Ndukwe | E8: Operations | F8: Capex | G8: Facility Expansion | H8: 36878797 | I8: 41394630 | J8: =H8-I8 -> -4515832.3 | K8: Rejected
A9: FIN00008 | B9: 45795 | C9: EMP0056 | D9: =IFERROR(INDEX(Dim_Employee!$B$2:$B$76,MATCH(C9,Dim_Employee!$A$2:$A$76,0)),"") -> Tunde Ndukwe | E9: IT | F9: Capex | G9: Facility Expansion | H9: 581857.02 | I9: 597957.07 | J9: =H9-I9 -> -16100.05 | K9: Approved
A10: FIN00009 | B10: 45986 | C10: EMP0051 | D10: =IFERROR(INDEX(Dim_Employee!$B$2:$B$76,MATCH(C10,Dim_Employee!$A$2:$A$76,0)),"") -> Ngozi Ndukwe | E10: Supply Chain | F10: Opex | G10: Fuel Cost | H10: 29047371 | I10: 30101364 | J10: =H10-I10 -> -1053993 | K10: Pending Approval
A11: FIN00010 | B11: 45778 | C11: EMP0057 | D11: =IFERROR(INDEX(Dim_Employee!$B$2:$B$76,MATCH(C11,Dim_Employee!$A$2:$A$76,0)),"") -> Abdullahi Ojo | E11: Human Resources | F11: Revenue | G11: Ancillary Services | H11: 6309914.2 | I11: 5535180.4 | J11: =H11-I11 -> 774733.72 | K11: Approved
A12: FIN00011 | B12: 45876 | C12: EMP0054 | D12: =IFERROR(INDEX(Dim_Employee!$B$2:$B$76,MATCH(C12,Dim_Employee!$A$2:$A$76,0)),"") -> Titilayo Chukwu | E12: Admin | F12: Revenue | G12: Capacity Payment | H12: 52980680 | I12: 54218318 | J12: =H12-I12 -> -1237638.2 | K12: Approved
