Workbook

Sheet Cover
B2: Python Statistical Analytics - Practical Training Workbook
B3: A comprehensive dataset and worked-statistics companion for the Python Statistical Analytics course
B5: Prepared by:
B6: Kajola Gbenga
B7: Data Scientist & AI Engineer
B10: Workbook Map
B11: Sheet | C11: Purpose
B12: Cover | C12: Title page and workbook guide
B13: Data_Dictionary | C13: Definitions of every column used across the workbook
B14: Raw_Data | C14: The 400-row employee dataset used throughout the practical
B15: TimeSeries_Data | C15: 60-month revenue series used for time-series analysis
B16: Descriptive_Stats | C16: Live formulas: mean, median, mode, variance, std, skew, kurtosis, quartiles
B17: Frequency_Tables | C17: Counts and percentages for every categorical variable
B18: Correlation_Matrix | C18: Pearson correlation matrix across numeric variables
B19: Group_Comparisons | C19: Group means/SD by Department and Gender, feeding ANOVA/t-tests
B20: Charts | C20: Histogram, boxplot-style, bar and line charts built from the data
B21: Instructions | C21: How to use this workbook alongside the notebook, Word guide and HTML guide
B23: Prepared by Kajola Gbenga - Data Scientist & AI Engineer

Sheet Data_Dictionary
B2: Data Dictionary - employee_statistics_dataset.csv
B4: Column | C4: Type | D4: Description / Statistical Use
B5: EmployeeID | C5: Text | D5: Unique identifier for each employee record
B6: Department | C6: Categorical (4 levels) | D6: Sales, Engineering, Marketing, Operations - used for one-way/two-way ANOVA and Kruskal-Wallis
B7: Gender | C7: Categorical (2 levels) | D7: Male, Female - used for independent-samples t-test and Mann-Whitney U
B8: Region | C8: Categorical (3 levels) | D8: North, South, West - used for chi-square test of independence
B9: Education | C9: Categorical (4 levels, ordinal) | D9: Diploma, Bachelors, Masters, PhD - contains missing values for imputation practice
B10: Age | C10: Numeric (discrete) | D10: Employee age in years
B11: YearsExperience | C11: Numeric (continuous) | D11: Years of professional experience - predictor in regression
B12: TrainingHours | C12: Numeric (continuous) | D12: Hours of training completed in the past year - contains missing values
B13: PreTrainingScore | C13: Numeric (continuous) | D13: Assessment score before a training intervention - paired with PostTrainingScore
B14: PostTrainingScore | C14: Numeric (continuous) | D14: Assessment score after the training intervention - used for paired t-test
B15: PerformanceScore | C15: Numeric (continuous, 0-100) | D15: Overall performance rating - main regression target
... B19: Promoted | C19: Binary (0/1) | D19: Whether the employee was promoted - target for logistic regression
B22: Data Dictionary - monthly_revenue_timeseries.csv
B24: Column | C24: Type | D24: Description / Statistical Use
B25: Date | C25: Date (monthly) | D25: First day of each month, Jan 2020 to Dec 2024
B26: MonthlyRevenue | C26: Numeric (continuous) | D26: Simulated monthly revenue with trend + seasonality + noise
B27: MarketingSpend | C27: Numeric (continuous) | D27: Simulated monthly marketing spend
B28: UnitsSold | C28: Numeric (discrete) | D28: Units sold per month, correlated with revenue
B30: Prepared by Kajola Gbenga - Data Scientist & AI Engineer

Sheet Raw_Data
A1: EmployeeID | B1: Department | C1: Gender | D1: Region | E1: Education | F1: Age | G1: YearsExperience | H1: TrainingHours | I1: PreTrainingScore | J1: PostTrainingScore | K1: PerformanceScore | L1: MonthlySales | M1: SatisfactionScore | N1: AttendanceRate | O1: Promoted
A2: EMP1000 | B2: Marketing | C2: Male | D2: South | E2: Bachelors | F2: 27 | G2: 4.7 | H2: 42 | I2: 67.2 | J2: 80.4 | K2: 89.1 | L2: 5566.48 | M2: 7 | N2: 94.8 | O2: 1
A3: EMP1001 | B3: Engineering | C3: Female | D3: North | E3: Bachelors | F3: 30 | G3: 6.4 | H3: 32.3 | I3: 61.1 | J3: 74.5 | K3: 75.8 | L3: 4573.74 | M3: 8 | N3: 94.7 | O3: 1
A4: EMP1002 | B4: Operations | C4: Female | D4: West | E4: Masters | F4: 29 | G4: 3.4 | H4: 36.7 | I4: 47.4 | J4: 57.5 | K4: 72.5 | L4: 4925.33 | M4: 8 | N4: 91.2 | O4: 1
A5: EMP1003 | B5: Marketing | C5: Male | D5: South | E5: Masters | F5: 24 | G5: 2.3 | H5: 37.2 | I5: 58.3 | J5: 64.5 | K5: 75.5 | L5: 5995.71 | M5: 8 | N5: 90 | O5: 0
A6: EMP1004 | B6: Sales | C6: Female | D6: North | E6: Diploma | F6: 21 | G6: 3 | H6: 31.2 | I6: 73.8 | J6: 80.8 | K6: 91 | L6: 4875.2 | M6: 6 | N6: 82.1 | O6: 0
A7: EMP1005 | B7: Operations | C7: Female | D7: North | E7: Diploma | F7: 28 | G7: 4 | H7: 45.8 | I7: 76.8 | J7: 81.6 | K7: 89.6 | L7: 5551.36 | M7: 8 | N7: 97.8 | O7: 1
A8: EMP1006 | B8: Marketing | C8: Male | D8: South | E8: Masters | F8: 21 | G8: 2.3 | H8: 42.9 | I8: 67.2 | J8: 71.2 | K8: 82 | L8: 3881.78 | M8: 6 | N8: 95.2 | O8: 0
A9: EMP1007 | B9: Marketing | C9: Female | D9: North | E9: Bachelors | F9: 37 | G9: 6.5 | H9: 38.9 | I9: 48.1 | J9: 51.9 | K9: 77.6 | L9: 7922.38 | M9: 6 | N9: 92.1 | O9: 0
A10: EMP1008 | B10: Sales | C10: Male | D10: South | E10: Bachelors | F10: 36 | G10: 8.3 | H10: 34.8 | I10: 64.9 | J10: 70.4 | K10: 77.9 | L10: 7378.64 | M10: 6 | N10: 92.3 | O10: 1
A11: EMP1009 | B11: Engineering | C11: Female | D11: West | E11: Bachelors | F11: 21 | G11: 0.9 | H11: 49.6 | I11: 68.5 | J11: 72.4 | K11: 84.5 | L11: 6169.41 | M11: 5 | N11: 96.7 | O11: 0
A12: EMP1010 | B12: Engineering | C12: Female | D12: North | E12: Masters | F12: 30 | G12: 6.1 | H12: 37.2 | I12: 67.3 | J12: 69 | K12: 76.3 | L12: 7028.45 | M12: 9 | N12: 85.2 | O12: 1
A13: EMP1011 | B13: Operations | C13: Female | D13: North | E13: Masters | F13: 25 | G13: 5.3 | H13: 36.3 | I13: 67.8 | J13: 76.7 | K13: 76.6 | L13: 6445.04 | M13: 8 | N13: 90.1 | O13: 0
... A18: EMP1016 | B18: Engineering | C18: Male | D18: West | E18: Bachelors | F18: 31 | G18: 6.1 | H18: 17.3 | I18: 63.4 | J18: 72.7 | K18: 80.6 | L18: 5926.32 | M18: 8 | N18: 85.4 | O18: 0
A19: EMP1017 | B19: Sales | C19: Female | D19: South | E19: Bachelors | F19: 36 | G19: 9.3 | H19: 42.6 | I19: 61.9 | J19: 68.9 | K19: 83.8 | L19: 6868.58 | N19: 92.3 | O19: 1
A20: EMP1018 | B20: Operations | C20: Male | D20: South | E20: Masters | F20: 21 | G20: 0 | H20: 58.9 | I20: 65.6 | J20: 76.6 | K20: 76.9 | L20: 5928.45 | M20: 8 | N20: 90.6 | O20: 1
A21: EMP1019 | B21: Marketing | C21: Female | D21: North | E21: Diploma | F21: 40 | G21: 7.1 | H21: 45.9 | I21: 46.6 | J21: 57.7 | K21: 83.2 | L21: 5949.22 | M21: 8 | N21: 86.4 | O21: 1
A22: EMP1020 | B22: Marketing | C22: Female | D22: North | E22: Diploma | F22: 37 | G22: 9.8 | H22: 42 | I22: 66.5 | J22: 75.8 | K22: 85.4 | L22: 8765.06 | M22: 5 | N22: 100 | O22: 0
A23: EMP1021 | B23: Engineering | C23: Male | D23: South | E23: Bachelors | F23: 37 | G23: 5.5 | H23: 33.3 | I23: 80.5 | J23: 87.5 | K23: 87.1 | L23: 5418.54 | M23: 5 | N23: 94.6 | O23: 0
A24: EMP1022 | B24: Operations | C24: Male | D24: North | E24: Masters | F24: 39 | G24: 7.8 | H24: 40.4 | I24: 60.8 | J24: 67.4 | K24: 73.4 | L24: 7117.98 | M24: 6 | N24: 95.4 | O24: 1
A25: EMP1023 | B25: Operations | C25: Male | D25: South | E25: Masters | F25: 23 | G25: 3.8 | H25: 37 | I25: 59.4 | J25: 61.9 | K25: 72.2 | L25: 6472.38 | M25: 8 | N25: 89.5 | O25: 1
A26: EMP1024 | B26: Marketing | C26: Female | D26: West | E26: Bachelors | F26: 29 | G26: 5.6 | H26: 30.6 | I26: 63.1 | J26: 67.9 | K26: 80.6 | L26: 6179.29 | N26: 96.6 | O26: 1
A27: EMP1025 | B27: Sales | C27: Female | D27: North | E27: Masters | F27: 21 | G27: 0.8 | H27: 36.5 | I27: 80.3 | J27: 85.8 | K27: 66.9 | L27: 4748.52 | M27: 5 | N27: 91.1 | O27: 0
A28: EMP1026 | B28: Engineering | C28: Male | D28: South | E28: Bachelors | F28: 22 | G28: 0 | H28: 42.4 | I28: 49.8 | J28: 53.3 | K28: 63.6 | L28: 4659.72 | M28: 5 | N28: 91.6 | O28: 0
A29: EMP1027 | B29: Sales | C29: Female | D29: North | E29: Bachelors | F29: 36 | G29: 9 | H29: 30.8 | I29: 62 | J29: 71.8 | K29: 88.7 | L29: 6761.7 | M29: 6 | N29: 96.1 | O29: 1
A30: EMP1028 | B30: Sales | C30: Male | D30: West | E30: PhD | F30: 35 | G30: 2.8 | H30: 30.3 | I30: 52 | J30: 64.8 | K30: 80.5 | L30: 4600.47 | M30: 6 | N30: 84.9 | O30: 0
A31: EMP1029 | B31: Marketing | C31: Female | D31: North | E31: Diploma | F31: 26 | G31: 4.5 | H31: 23.7 | I31: 54.5 | J31: 58.9 | K31: 71.1 | L31: 4734.96 | M31: 5 | N31: 100 | O31: 1
A32: EMP1030 | B32: Marketing | C32: Female | D32: South | E32: Bachelors | F32: 25 | G32: 1.6 | H32: 44.7 | I32: 59.5 | J32: 68.6 | K32: 59.8 | L32: 6416.63 | M32: 5 | N32: 93.9 | O32: 0
A33: EMP1031 | B33: Operations | C33: Female | D33: South | E33: Bachelors | F33: 26 | G33: 1.5 | H33: 46.5 | I33: 73.5 | J33: 77.4 | K33: 79.9 | L33: 5335.82 | M33: 6 | N33: 99.4 | O33: 1
A34: EMP1032 | B34: Engineering | C34: Female | D34: North | E34: Bachelors | F34: 31 | G34: 5.4 | H34: 42.8 | I34: 78 | J34: 84.8 | K34: 73.1 | L34: 5451.28 | M34: 7 | N34: 87.6 | O34: 1
A35: EMP1033 | B35: Engineering | C35: Female | D35: South | E35: Masters | F35: 28 | G35: 3.7 | I35: 64.5 | J35: 69.7 | K35: 86.9 | L35: 5827.83 | M35: 5 | N35: 88.4 | O35: 1
A36: EMP1034 | B36: Engineering | C36: Male | D36: South | E36: Bachelors | F36: 30 | G36: 7.2 | H36: 41.1 | I36: 56.2 | J36: 66.6 | K36: 81.1 | L36: 7650.83 | M36: 7 | N36: 87.2 | O36: 1
A37: EMP1035 | B37: Sales | C37: Male | D37: South | E37: Diploma | F37: 34 | G37: 7.4 | H37: 44.7 | I37: 84.9 | J37: 90.2 | K37: 77.8 | L37: 7413.05 | N37: 94.3 | O37: 0
A38: EMP1036 | B38: Sales | C38: Male | D38: West | E38: Bachelors | F38: 35 | G38: 7 | H38: 43.6 | I38: 55.7 | J38: 67.7 | K38: 81.8 | L38: 7225.3 | M38: 5 | N38: 93.3 | O38: 1
A39: EMP1037 | B39: Engineering | C39: Male | D39: West | E39: Bachelors | F39: 34 | G39: 6.8 | H39: 38.9 | I39: 54.3 | J39: 61.3 | K39: 84.6 | L39: 6293.23 | M39: 7 | N39: 90.7 | O39: 0
A40: EMP1038 | B40: Sales | C40: Female | D40: South | E40: Bachelors | F40: 41 | G40: 11 | H40: 33.6 | I40: 42.3 | J40: 47.7 | K40: 84.1 | L40: 7871.53 | N40: 87.9 | O40: 1
A41: EMP1039 | B41: Marketing | C41: Female | D41: South | F41: 30 | G41: 2.6 | H41: 66.6 | I41: 74 | J41: 77 | K41: 87.1 | L41: 6041.29 | M41: 6 | N41: 86.7 | O41: 0
A42: EMP1040 | B42: Engineering | C42: Female | D42: North | F42: 34 | G42: 5.8 | I42: 69.7 | J42: 78.7 | K42: 79.4 | L42: 5791.35 | M42: 6 | N42: 92.8 | O42: 0
A43: EMP1041 | B43: Operations | C43: Male | D43: West | E43: Bachelors | F43: 38 | G43: 9.6 | I43: 84.2 | J43: 95.8 | K43: 91.3 | L43: 7922.32 | M43: 9 | N43: 90.7 | O43: 1
A44: EMP1042 | B44: Marketing | C44: Female | D44: South | E44: Bachelors | F44: 34 | G44: 10 | H44: 45.2 | I44: 46.1 | J44: 55.2 | K44: 90.8 | L44: 8456.85 | M44: 7 | N44: 89.6 | O44: 1
...

Sheet TimeSeries_Data
A1: Date | B1: MonthlyRevenue | C1: MarketingSpend | D1: UnitsSold
A2: 2020-01-01 | B2: 15802.19 | C2: 2001.85 | D2: 393
A3: 2020-02-01 | B3: 16186.81 | C3: 2272.19 | D3: 379
A4: 2020-03-01 | B4: 17881.72 | C4: 2501.13 | D4: 403
A5: 2020-04-01 | B5: 17799.53 | C5: 2551.06 | D5: 427
A6: 2020-05-01 | B6: 17581.83 | C6: 2400.32 | D6: 391
A7: 2020-06-01 | B7: 17564.93 | C7: 2421.55 | D7: 518
A8: 2020-07-01 | B8: 16858.43 | C8: 2430.51 | D8: 381
A9: 2020-08-01 | B9: 15057.21 | C9: 1986.13 | D9: 342
A10: 2020-09-01 | B10: 14749.83 | C10: 1972.99 | D10: 259
A11: 2020-10-01 | B11: 14650.98 | C11: 1823.46 | D11: 304
A12: 2020-11-01 | B12: 15501.77 | C12: 1791.9 | D12: 390
A13: 2020-12-01 | B13: 17148.68 | C13: 2260.72 | D13: 328
... A61: 2024-12-01 | B61: 27147.42 | C61: 3454.35 | D61: 610
B63: Prepared by Kajola Gbenga - Data Scientist & AI Engineer

Sheet Descriptive_Stats
B2: Descriptive Statistics (live formulas referencing Raw_Data)
B4: Statistic | C4: Age | D4: YearsExperience | E4: TrainingHours | F4: PreTrainingScore | G4: PostTrainingScore | H4: PerformanceScore | I4: MonthlySales | J4: SatisfactionScore | K4: AttendanceRate
B5: Count (N) | C5: =COUNT(Raw_Data!$F$2:$F$401) -> 400 | D5: =COUNT(Raw_Data!$G$2:$G$401) -> 400 | E5: =COUNT(Raw_Data!$H$2:$H$401) -> 388 | F5: =COUNT(Raw_Data!$I$2:$I$401) -> 400 | G5: =COUNT(Raw_Data!$J$2:$J$401) -> 400 | H5: =COUNT(Raw_Data!$K$2:$K$401) -> 400 | I5: =COUNT(Raw_Data!$L$2:$L$401) -> 400 | J5: =COUNT(Raw_Data!$M$2:$M$401) -> 390 | K5: =COUNT(Raw_Data!$N$2:$N$401) -> 392
B6: Missing | C6: =400-COUNT(Raw_Data!$F$2:$F$401) -> 0 | D6: =400-COUNT(Raw_Data!$G$2:$G$401) -> 0 | E6: =400-COUNT(Raw_Data!$H$2:$H$401) -> 12 | F6: =400-COUNT(Raw_Data!$I$2:$I$401) -> 0 | G6: =400-COUNT(Raw_Data!$J$2:$J$401) -> 0 | H6: =400-COUNT(Raw_Data!$K$2:$K$401) -> 0 | I6: =400-COUNT(Raw_Data!$L$2:$L$401) -> 0 | J6: =400-COUNT(Raw_Data!$M$2:$M$401) -> 10 | K6: =400-COUNT(Raw_Data!$N$2:$N$401) -> 8
B7: Mean | C7: =AVERAGE(Raw_Data!$F$2:$F$401) -> 31.0175 | D7: =AVERAGE(Raw_Data!$G$2:$G$401) -> 5.495 | E7: =AVERAGE(Raw_Data!$H$2:$H$401) -> 40.520103 | F7: =AVERAGE(Raw_Data!$I$2:$I$401) -> 59.85575 | G7: =AVERAGE(Raw_Data!$J$2:$J$401) -> 67.92775 | H7: =AVERAGE(Raw_Data!$K$2:$K$401) -> 81.38175 | I7: =AVERAGE(Raw_Data!$L$2:$L$401) -> 6587.5075 | J7: =AVERAGE(Raw_Data!$M$2:$M$401) -> 6.9846154 | K7: =AVERAGE(Raw_Data!$N$2:$N$401) -> 92.668878
B8: Median | C8: =MEDIAN(Raw_Data!$F$2:$F$401) -> 30 | D8: =MEDIAN(Raw_Data!$G$2:$G$401) -> 5.5 | E8: =MEDIAN(Raw_Data!$H$2:$H$401) -> 41.2 | F8: =MEDIAN(Raw_Data!$I$2:$I$401) -> 59.5 | G8: =MEDIAN(Raw_Data!$J$2:$J$401) -> 67.95 | H8: =MEDIAN(Raw_Data!$K$2:$K$401) -> 81.7 | I8: =MEDIAN(Raw_Data!$L$2:$L$401) -> 6269.755 | J8: =MEDIAN(Raw_Data!$M$2:$M$401) -> 7 | K8: =MEDIAN(Raw_Data!$N$2:$N$401) -> 92.85
B9: Mode | C9: =IFERROR(_xlfn.MODE.SNGL(Raw_Data!$F$2:$F$401),"No exact mode") -> 28 | D9: =IFERROR(_xlfn.MODE.SNGL(Raw_Data!$G$2:$G$401),"No exact mode") -> 0 | E9: =IFERROR(_xlfn.MODE.SNGL(Raw_Data!$H$2:$H$401),"No exact mode") -> 38.9 | F9: =IFERROR(_xlfn.MODE.SNGL(Raw_Data!$I$2:$I$401),"No exact mode") -> 58.3 | G9: =IFERROR(_xlfn.MODE.SNGL(Raw_Data!$J$2:$J$401),"No exact mode") -> 64.5 | H9: =IFERROR(_xlfn.MODE.SNGL(Raw_Data!$K$2:$K$401),"No exact mode") -> 100 | I9: =IFERROR(_xlfn.MODE.SNGL(Raw_Data!$L$2:$L$401),"No exact mode") -> No exact mode | J9: =IFERROR(_xlfn.MODE.SNGL(Raw_Data!$M$2:$M$401),"No exact mode") -> 7 | K9: =IFERROR(_xlfn.MODE.SNGL(Raw_Data!$N$2:$N$401),"No exact mode") -> 100
B10: Std Dev (sample) | C10: =_xlfn.STDEV.S(Raw_Data!$F$2:$F$401) -> 5.885047 | D10: =_xlfn.STDEV.S(Raw_Data!$G$2:$G$401) -> 3.115476 | E10: =_xlfn.STDEV.S(Raw_Data!$H$2:$H$401) -> 11.901068 | F10: =_xlfn.STDEV.S(Raw_Data!$I$2:$I$401) -> 10.167606 | G10: =_xlfn.STDEV.S(Raw_Data!$J$2:$J$401) -> 10.896724 | H10: =_xlfn.STDEV.S(Raw_Data!$K$2:$K$401) -> 10.257809 | I10: =_xlfn.STDEV.S(Raw_Data!$L$2:$L$401) -> 3256.2776 | J10: =_xlfn.STDEV.S(Raw_Data!$M$2:$M$401) -> 1.537791 | K10: =_xlfn.STDEV.S(Raw_Data!$N$2:$N$401) -> 4.6423989
B11: Variance (sample) | C11: =_xlfn.VAR.S(Raw_Data!$F$2:$F$401) -> 34.633778 | D11: =_xlfn.VAR.S(Raw_Data!$G$2:$G$401) -> 9.7061905 | E11: =_xlfn.VAR.S(Raw_Data!$H$2:$H$401) -> 141.63541 | F11: =_xlfn.VAR.S(Raw_Data!$I$2:$I$401) -> 103.38022 | G11: =_xlfn.VAR.S(Raw_Data!$J$2:$J$401) -> 118.7386 | H11: =_xlfn.VAR.S(Raw_Data!$K$2:$K$401) -> 105.22265 | I11: =_xlfn.VAR.S(Raw_Data!$L$2:$L$401) -> 10603344 | J11: =_xlfn.VAR.S(Raw_Data!$M$2:$M$401) -> 2.3648013 | K11: =_xlfn.VAR.S(Raw_Data!$N$2:$N$401) -> 21.551868
B12: Minimum | C12: =MIN(Raw_Data!$F$2:$F$401) -> 21 | D12: =MIN(Raw_Data!$G$2:$G$401) -> 0 | E12: =MIN(Raw_Data!$H$2:$H$401) -> 5 | F12: =MIN(Raw_Data!$I$2:$I$401) -> 33.7 | G12: =MIN(Raw_Data!$J$2:$J$401) -> 39.3 | H12: =MIN(Raw_Data!$K$2:$K$401) -> 57.9 | I12: =MIN(Raw_Data!$L$2:$L$401) -> 2159.96 | J12: =MIN(Raw_Data!$M$2:$M$401) -> 3 | K12: =MIN(Raw_Data!$N$2:$N$401) -> 77.3
B13: Maximum | C13: =MAX(Raw_Data!$F$2:$F$401) -> 49 | D13: =MAX(Raw_Data!$G$2:$G$401) -> 15.3 | E13: =MAX(Raw_Data!$H$2:$H$401) -> 74.3 | F13: =MAX(Raw_Data!$I$2:$I$401) -> 88.5 | G13: =MAX(Raw_Data!$J$2:$J$401) -> 100 | H13: =MAX(Raw_Data!$K$2:$K$401) -> 100 | I13: =MAX(Raw_Data!$L$2:$L$401) -> 38815.792 | J13: =MAX(Raw_Data!$M$2:$M$401) -> 10 | K13: =MAX(Raw_Data!$N$2:$N$401) -> 100
B14: Range | C14: =MAX(Raw_Data!$F$2:$F$401)-MIN(Raw_Data!$F$2:$F$401) -> 28 | D14: =MAX(Raw_Data!$G$2:$G$401)-MIN(Raw_Data!$G$2:$G$401) -> 15.3 | E14: =MAX(Raw_Data!$H$2:$H$401)-MIN(Raw_Data!$H$2:$H$401) -> 69.3 | F14: =MAX(Raw_Data!$I$2:$I$401)-MIN(Raw_Data!$I$2:$I$401) -> 54.8 | G14: =MAX(Raw_Data!$J$2:$J$401)-MIN(Raw_Data!$J$2:$J$401) -> 60.7 | H14: =MAX(Raw_Data!$K$2:$K$401)-MIN(Raw_Data!$K$2:$K$401) -> 42.1 | I14: =MAX(Raw_Data!$L$2:$L$401)-MIN(Raw_Data!$L$2:$L$401) -> 36655.832 | J14: =MAX(Raw_Data!$M$2:$M$401)-MIN(Raw_Data!$M$2:$M$401) -> 7 | K14: =MAX(Raw_Data!$N$2:$N$401)-MIN(Raw_Data!$N$2:$N$401) -> 22.7
B15: 25th Percentile (Q1) | C15: =_xlfn.QUARTILE.INC(Raw_Data!$F$2:$F$401,1) -> 27 | D15: =_xlfn.QUARTILE.INC(Raw_Data!$G$2:$G$401,1) -> 3.2 | E15: =_xlfn.QUARTILE.INC(Raw_Data!$H$2:$H$401,1) -> 33.125 | F15: =_xlfn.QUARTILE.INC(Raw_Data!$I$2:$I$401,1) -> 52.6 | G15: =_xlfn.QUARTILE.INC(Raw_Data!$J$2:$J$401,1) -> 60.775 | H15: =_xlfn.QUARTILE.INC(Raw_Data!$K$2:$K$401,1) -> 74.35 | I15: =_xlfn.QUARTILE.INC(Raw_Data!$L$2:$L$401,1) -> 5353.085 | J15: =_xlfn.QUARTILE.INC(Raw_Data!$M$2:$M$401,1) -> 6 | K15: =_xlfn.QUARTILE.INC(Raw_Data!$N$2:$N$401,1) -> 89.5
B16: 75th Percentile (Q3) | C16: =_xlfn.QUARTILE.INC(Raw_Data!$F$2:$F$401,3) -> 35 | D16: =_xlfn.QUARTILE.INC(Raw_Data!$G$2:$G$401,3) -> 7.6 | E16: =_xlfn.QUARTILE.INC(Raw_Data!$H$2:$H$401,3) -> 47.525 | F16: =_xlfn.QUARTILE.INC(Raw_Data!$I$2:$I$401,3) -> 66.325 | G16: =_xlfn.QUARTILE.INC(Raw_Data!$J$2:$J$401,3) -> 74.425 | H16: =_xlfn.QUARTILE.INC(Raw_Data!$K$2:$K$401,3) -> 89.4 | I16: =_xlfn.QUARTILE.INC(Raw_Data!$L$2:$L$401,3) -> 7240.3725 | J16: =_xlfn.QUARTILE.INC(Raw_Data!$M$2:$M$401,3) -> 8 | K16: =_xlfn.QUARTILE.INC(Raw_Data!$N$2:$N$401,3) -> 96
B17: Interquartile Range (IQR) | C17: =C16-C15 -> 8 | D17: =D16-D15 -> 4.4 | E17: =E16-E15 -> 14.4 | F17: =F16-F15 -> 13.725 | G17: =G16-G15 -> 13.65 | H17: =H16-H15 -> 15.05 | I17: =I16-I15 -> 1887.2875 | J17: =J16-J15 -> 2 | K17: =K16-K15 -> 6.5
B18: Skewness | C18: =SKEW(Raw_Data!$F$2:$F$401) -> 0.24923351 | D18: =SKEW(Raw_Data!$G$2:$G$401) -> 0.18947878 | E18: =SKEW(Raw_Data!$H$2:$H$401) -> -0.049230324 | F18: =SKEW(Raw_Data!$I$2:$I$401) -> 0.1965002 | G18: =SKEW(Raw_Data!$J$2:$J$401) -> 0.1043158 | H18: =SKEW(Raw_Data!$K$2:$K$401) -> -0.23684693 | I18: =SKEW(Raw_Data!$L$2:$L$401) -> 7.2033125 | J18: =SKEW(Raw_Data!$M$2:$M$401) -> -0.15741496 | K18: =SKEW(Raw_Data!$N$2:$N$401) -> -0.44090081
B19: Kurtosis | C19: =KURT(Raw_Data!$F$2:$F$401) -> -0.48036907 | D19: =KURT(Raw_Data!$G$2:$G$401) -> -0.32861737 | E19: =KURT(Raw_Data!$H$2:$H$401) -> 0.41852221 | F19: =KURT(Raw_Data!$I$2:$I$401) -> -0.10738589 | G19: =KURT(Raw_Data!$J$2:$J$401) -> -0.058729499 | H19: =KURT(Raw_Data!$K$2:$K$401) -> -0.63556791 | I19: =KURT(Raw_Data!$L$2:$L$401) -> 63.857284 | J19: =KURT(Raw_Data!$M$2:$M$401) -> -0.46641375 | K19: =KURT(Raw_Data!$N$2:$N$401) -> 0.042325417
B20: Coefficient of Variation (%) | C20: =(C10/C7)*100 -> 18.973312 | D20: =(D10/D7)*100 -> 56.69656 | E20: =(E10/E7)*100 -> 29.370773 | F20: =(F10/F7)*100 -> 16.98685 | G20: =(G10/G7)*100 -> 16.041639 | H20: =(H10/H7)*100 -> 12.604557 | I20: =(I10/I7)*100 -> 49.431103 | J20: =(J10/J7)*100 -> 22.016832 | K20: =(K10/K7)*100 -> 5.0096635
B23: Note: every cell above is a live Excel formula pointing at Raw_Data. Change a value in Raw_Data and these statistics recalculate automatically.
B25: Prepared by Kajola Gbenga - Data Scientist & AI Engineer

Sheet Frequency_Tables
B2: Frequency Tables (live formulas)
B4: Variable: Department
B5: Category | C5: Count | D5: Percent (%)
B6: Engineering | C6: =COUNTIF(Raw_Data!$B$2:$B$401,"Engineering") -> 123 | D6: =C6/COUNTA(Raw_Data!$A$2:$A$401)*100 -> 30.75
B7: Marketing | C7: =COUNTIF(Raw_Data!$B$2:$B$401,"Marketing") -> 81 | D7: =C7/COUNTA(Raw_Data!$A$2:$A$401)*100 -> 20.25
B8: Operations | C8: =COUNTIF(Raw_Data!$B$2:$B$401,"Operations") -> 75 | D8: =C8/COUNTA(Raw_Data!$A$2:$A$401)*100 -> 18.75
B9: Sales | C9: =COUNTIF(Raw_Data!$B$2:$B$401,"Sales") -> 121 | D9: =C9/COUNTA(Raw_Data!$A$2:$A$401)*100 -> 30.25
B12: Variable: Gender
B13: Category | C13: Count | D13: Percent (%)
B14: Female | C14: =COUNTIF(Raw_Data!$C$2:$C$401,"Female") -> 188 | D14: =C14/COUNTA(Raw_Data!$A$2:$A$401)*100 -> 47
B15: Male | C15: =COUNTIF(Raw_Data!$C$2:$C$401,"Male") -> 212 | D15: =C15/COUNTA(Raw_Data!$A$2:$A$401)*100 -> 53
B18: Variable: Region
B19: Category | C19: Count | D19: Percent (%)
B20: North | C20: =COUNTIF(Raw_Data!$D$2:$D$401,"North") -> 156 | D20: =C20/COUNTA(Raw_Data!$A$2:$A$401)*100 -> 39
B21: South | C21: =COUNTIF(Raw_Data!$D$2:$D$401,"South") -> 135 | D21: =C21/COUNTA(Raw_Data!$A$2:$A$401)*100 -> 33.75
B22: West | C22: =COUNTIF(Raw_Data!$D$2:$D$401,"West") -> 109 | D22: =C22/COUNTA(Raw_Data!$A$2:$A$401)*100 -> 27.25
B25: Variable: Education
B26: Category | C26: Count | D26: Percent (%)
B27: Diploma | C27: =COUNTIF(Raw_Data!$E$2:$E$401,"Diploma") -> 54 | D27: =C27/COUNTA(Raw_Data!$A$2:$A$401)*100 -> 13.5
B28: Bachelors | C28: =COUNTIF(Raw_Data!$E$2:$E$401,"Bachelors") -> 192 | D28: =C28/COUNTA(Raw_Data!$A$2:$A$401)*100 -> 48
B29: Masters | C29: =COUNTIF(Raw_Data!$E$2:$E$401,"Masters") -> 104 | D29: =C29/COUNTA(Raw_Data!$A$2:$A$401)*100 -> 26
B30: PhD | C30: =COUNTIF(Raw_Data!$E$2:$E$401,"PhD") -> 44 | D30: =C30/COUNTA(Raw_Data!$A$2:$A$401)*100 -> 11
B33: Variable: Promoted
B34: Category | C34: Count | D34: Percent (%)
B35: 0 | C35: =COUNTIF(Raw_Data!$O$2:$O$401,0) -> 148 | D35: =C35/COUNTA(Raw_Data!$A$2:$A$401)*100 -> 37
B36: 1 | C36: =COUNTIF(Raw_Data!$O$2:$O$401,1) -> 252 | D36: =C36/COUNTA(Raw_Data!$A$2:$A$401)*100 -> 63
B38: Prepared by Kajola Gbenga - Data Scientist & AI Engineer

Sheet Correlation_Matrix
B2: Pearson Correlation Matrix (live formulas, numeric variables)
C4: Age | D4: YearsExperience | E4: TrainingHours | F4: PerformanceScore | G4: MonthlySales | H4: SatisfactionScore | I4: AttendanceRate
B5: Age | C5: =CORREL(Raw_Data!$F$2:$F$401,Raw_Data!$F$2:$F$401) -> 1 | D5: =CORREL(Raw_Data!$F$2:$F$401,Raw_Data!$G$2:$G$401) -> 0.87466168 | E5: =CORREL(Raw_Data!$F$2:$F$401,Raw_Data!$H$2:$H$401) -> -0.065907203 | F5: =CORREL(Raw_Data!$F$2:$F$401,Raw_Data!$K$2:$K$401) -> 0.46857494 | G5: =CORREL(Raw_Data!$F$2:$F$401,Raw_Data!$L$2:$L$401) -> 0.21075305 | H5: =CORREL(Raw_Data!$F$2:$F$401,Raw_Data!$M$2:$M$401) -> -0.1229166 | I5: =CORREL(Raw_Data!$F$2:$F$401,Raw_Data!$N$2:$N$401) -> -0.048235011
B6: YearsExperience | C6: =CORREL(Raw_Data!$G$2:$G$401,Raw_Data!$F$2:$F$401) -> 0.87466168 | D6: =CORREL(Raw_Data!$G$2:$G$401,Raw_Data!$G$2:$G$401) -> 1 | E6: =CORREL(Raw_Data!$G$2:$G$401,Raw_Data!$H$2:$H$401) -> -0.045816478 | F6: =CORREL(Raw_Data!$G$2:$G$401,Raw_Data!$K$2:$K$401) -> 0.53203935 | G6: =CORREL(Raw_Data!$G$2:$G$401,Raw_Data!$L$2:$L$401) -> 0.29759009 | H6: =CORREL(Raw_Data!$G$2:$G$401,Raw_Data!$M$2:$M$401) -> -0.079592832 | I6: =CORREL(Raw_Data!$G$2:$G$401,Raw_Data!$N$2:$N$401) -> -0.02039256
B7: TrainingHours | C7: =CORREL(Raw_Data!$H$2:$H$401,Raw_Data!$F$2:$F$401) -> -0.065907203 | D7: =CORREL(Raw_Data!$H$2:$H$401,Raw_Data!$G$2:$G$401) -> -0.045816478 | E7: =CORREL(Raw_Data!$H$2:$H$401,Raw_Data!$H$2:$H$401) -> 1 | F7: =CORREL(Raw_Data!$H$2:$H$401,Raw_Data!$K$2:$K$401) -> 0.41219996 | G7: =CORREL(Raw_Data!$H$2:$H$401,Raw_Data!$L$2:$L$401) -> 0.16922769 | H7: =CORREL(Raw_Data!$H$2:$H$401,Raw_Data!$M$2:$M$401) -> 0.00038224851 | I7: =CORREL(Raw_Data!$H$2:$H$401,Raw_Data!$N$2:$N$401) -> -0.032409978
B8: PerformanceScore | C8: =CORREL(Raw_Data!$K$2:$K$401,Raw_Data!$F$2:$F$401) -> 0.46857494 | D8: =CORREL(Raw_Data!$K$2:$K$401,Raw_Data!$G$2:$G$401) -> 0.53203935 | E8: =CORREL(Raw_Data!$K$2:$K$401,Raw_Data!$H$2:$H$401) -> 0.41219996 | F8: =CORREL(Raw_Data!$K$2:$K$401,Raw_Data!$K$2:$K$401) -> 1 | G8: =CORREL(Raw_Data!$K$2:$K$401,Raw_Data!$L$2:$L$401) -> 0.30184365 | H8: =CORREL(Raw_Data!$K$2:$K$401,Raw_Data!$M$2:$M$401) -> -0.047524155 | I8: =CORREL(Raw_Data!$K$2:$K$401,Raw_Data!$N$2:$N$401) -> -0.012614339
B9: MonthlySales | C9: =CORREL(Raw_Data!$L$2:$L$401,Raw_Data!$F$2:$F$401) -> 0.21075305 | D9: =CORREL(Raw_Data!$L$2:$L$401,Raw_Data!$G$2:$G$401) -> 0.29759009 | E9: =CORREL(Raw_Data!$L$2:$L$401,Raw_Data!$H$2:$H$401) -> 0.16922769 | F9: =CORREL(Raw_Data!$L$2:$L$401,Raw_Data!$K$2:$K$401) -> 0.30184365 | G9: =CORREL(Raw_Data!$L$2:$L$401,Raw_Data!$L$2:$L$401) -> 1 | H9: =CORREL(Raw_Data!$L$2:$L$401,Raw_Data!$M$2:$M$401) -> -0.01677503 | I9: =CORREL(Raw_Data!$L$2:$L$401,Raw_Data!$N$2:$N$401) -> -0.038807826
B10: SatisfactionScore | C10: =CORREL(Raw_Data!$M$2:$M$401,Raw_Data!$F$2:$F$401) -> -0.1229166 | D10: =CORREL(Raw_Data!$M$2:$M$401,Raw_Data!$G$2:$G$401) -> -0.079592832 | E10: =CORREL(Raw_Data!$M$2:$M$401,Raw_Data!$H$2:$H$401) -> 0.00038224851 | F10: =CORREL(Raw_Data!$M$2:$M$401,Raw_Data!$K$2:$K$401) -> -0.047524155 | G10: =CORREL(Raw_Data!$M$2:$M$401,Raw_Data!$L$2:$L$401) -> -0.01677503 | H10: =CORREL(Raw_Data!$M$2:$M$401,Raw_Data!$M$2:$M$401) -> 1 | I10: =CORREL(Raw_Data!$M$2:$M$401,Raw_Data!$N$2:$N$401) -> -0.0030339368
B11: AttendanceRate | C11: =CORREL(Raw_Data!$N$2:$N$401,Raw_Data!$F$2:$F$401) -> -0.048235011 | D11: =CORREL(Raw_Data!$N$2:$N$401,Raw_Data!$G$2:$G$401) -> -0.02039256 | E11: =CORREL(Raw_Data!$N$2:$N$401,Raw_Data!$H$2:$H$401) -> -0.032409978 | F11: =CORREL(Raw_Data!$N$2:$N$401,Raw_Data!$K$2:$K$401) -> -0.012614339 | G11: =CORREL(Raw_Data!$N$2:$N$401,Raw_Data!$L$2:$L$401) -> -0.038807826 | H11: =CORREL(Raw_Data!$N$2:$N$401,Raw_Data!$M$2:$M$401) -> -0.0030339368 | I11: =CORREL(Raw_Data!$N$2:$N$401,Raw_Data!$N$2:$N$401) -> 1
B13: Prepared by Kajola Gbenga - Data Scientist & AI Engineer

Sheet Group_Comparisons
B2: Group Comparisons - feeds t-tests / ANOVA in the notebook and Word guide
B4: By Department: PerformanceScore
B5: Department | C5: N | D5: Mean | E5: Std Dev | F5: Min | G5: Max
B6: Engineering | C6: =COUNTIF(Raw_Data!$B$2:$B$401,"Engineering") -> 123 | D6: =AVERAGEIF(Raw_Data!$B$2:$B$401,"Engineering",Raw_Data!$K$2:$K$401) -> 85.870732 | E6: =SQRT(SUMPRODUCT((Raw_Data!$B$2:$B$401="Engineering")*(Raw_Data!$K$2:$K$401-AVERAGEIF(Raw_Data!$B$2:$B$401,"Engineering",Raw_Data!$K$2:$K$401))^2)/(COUNTIF(Raw_Data!$B$2:$B$401,"Engineering")-1)) -> 9.4051149 | F6: =_xlfn.MINIFS(Raw_Data!$K$2:$K$401,Raw_Data!$B$2:$B$401,"Engineering") -> 60.8 | G6: =_xlfn.MAXIFS(Raw_Data!$K$2:$K$401,Raw_Data!$B$2:$B$401,"Engineering") -> 100
B7: Marketing | C7: =COUNTIF(Raw_Data!$B$2:$B$401,"Marketing") -> 81 | D7: =AVERAGEIF(Raw_Data!$B$2:$B$401,"Marketing",Raw_Data!$K$2:$K$401) -> 78.250617 | E7: =SQRT(SUMPRODUCT((Raw_Data!$B$2:$B$401="Marketing")*(Raw_Data!$K$2:$K$401-AVERAGEIF(Raw_Data!$B$2:$B$401,"Marketing",Raw_Data!$K$2:$K$401))^2)/(COUNTIF(Raw_Data!$B$2:$B$401,"Marketing")-1)) -> 9.6934272 | F7: =_xlfn.MINIFS(Raw_Data!$K$2:$K$401,Raw_Data!$B$2:$B$401,"Marketing") -> 57.9 | G7: =_xlfn.MAXIFS(Raw_Data!$K$2:$K$401,Raw_Data!$B$2:$B$401,"Marketing") -> 100
B8: Operations | C8: =COUNTIF(Raw_Data!$B$2:$B$401,"Operations") -> 75 | D8: =AVERAGEIF(Raw_Data!$B$2:$B$401,"Operations",Raw_Data!$K$2:$K$401) -> 78.08 | E8: =SQRT(SUMPRODUCT((Raw_Data!$B$2:$B$401="Operations")*(Raw_Data!$K$2:$K$401-AVERAGEIF(Raw_Data!$B$2:$B$401,"Operations",Raw_Data!$K$2:$K$401))^2)/(COUNTIF(Raw_Data!$B$2:$B$401,"Operations")-1)) -> 9.9918616 | F8: =_xlfn.MINIFS(Raw_Data!$K$2:$K$401,Raw_Data!$B$2:$B$401,"Operations") -> 58.4 | G8: =_xlfn.MAXIFS(Raw_Data!$K$2:$K$401,Raw_Data!$B$2:$B$401,"Operations") -> 100
B9: Sales | C9: =COUNTIF(Raw_Data!$B$2:$B$401,"Sales") -> 121 | D9: =AVERAGEIF(Raw_Data!$B$2:$B$401,"Sales",Raw_Data!$K$2:$K$401) -> 80.961157 | E9: =SQRT(SUMPRODUCT((Raw_Data!$B$2:$B$401="Sales")*(Raw_Data!$K$2:$K$401-AVERAGEIF(Raw_Data!$B$2:$B$401,"Sales",Raw_Data!$K$2:$K$401))^2)/(COUNTIF(Raw_Data!$B$2:$B$401,"Sales")-1)) -> 10.072863 | F9: =_xlfn.MINIFS(Raw_Data!$K$2:$K$401,Raw_Data!$B$2:$B$401,"Sales") -> 59.9 | G9: =_xlfn.MAXIFS(Raw_Data!$K$2:$K$401,Raw_Data!$B$2:$B$401,"Sales") -> 100
B12: By Gender: PerformanceScore
B13: Gender | C13: N | D13: Mean | E13: Std Dev
B14: Female | C14: =COUNTIF(Raw_Data!$C$2:$C$401,"Female") -> 188 | D14: =AVERAGEIF(Raw_Data!$C$2:$C$401,"Female",Raw_Data!$K$2:$K$401) -> 82.530851
B15: Male | C15: =COUNTIF(Raw_Data!$C$2:$C$401,"Male") -> 212 | D15: =AVERAGEIF(Raw_Data!$C$2:$C$401,"Male",Raw_Data!$K$2:$K$401) -> 80.362736
B17: Note: Std Dev by Department uses an array formula IF(); it needs Ctrl+Shift+Enter in older Excel, or works natively in Excel 365.
B19: Prepared by Kajola Gbenga - Data Scientist & AI Engineer

Sheet Charts
B2: Charts built from Raw_Data and TimeSeries_Data
B4: Prepared by Kajola Gbenga - Data Scientist & AI Engineer

Sheet Instructions
B2: How to Use This Workbook
B4: 1. Start with the Data_Dictionary sheet to understand every column before touching formulas.
B5: 2. Raw_Data and TimeSeries_Data are the source tables - every other sheet reads from them live.
B6: 3. Descriptive_Stats, Frequency_Tables, Correlation_Matrix and Group_Comparisons use Excel formulas (AVERAGE, STDEV.S, CORREL, COUNTIF, AVERAGEIF, QUARTILE.INC, SKEW, KURT).
B7: 4. Edit any value in Raw_Data and watch the dependent sheets recalculate automatically - this is the fastest way to build intuition for how each statistic behaves.
B8: 5. Use this workbook side-by-side with employee_statistics_dataset.csv (same data, plain CSV), the Jupyter notebook (Python code for every statistic here plus hypothesis tests, regression and time series), the Word document (full theory + line-by-line code walkthrough) and the HTML guide (same content, browser-viewable).
B9: 6. Charts sheet demonstrates a bar chart, line chart and scatter chart built natively in Excel from the same data used in the notebook's matplotlib/seaborn plots - compare the two approaches.
B10: 7. Recommended teaching sequence: Data_Dictionary -> Raw_Data -> Descriptive_Stats -> Frequency_Tables -> Charts -> Correlation_Matrix -> Group_Comparisons -> switch to the notebook for hypothesis testing, regression, and time series.
B12: Prepared by Kajola Gbenga - Data Scientist & AI Engineer
